Workbook

Sheet 总览
A1: 家庭5年财务规划（2026-2030）
A2: 制定日期：2026年2月 | 规划周期：2026年2月 - 2030年12月
A4: 📋 基本财务假设
A5: 参数名 | B5: 初始值 | C5: 备注 | D5: 变更1生效 (YYYYMM) | E5: 变更1值 | F5: 变更2生效 (YYYYMM) | G5: 变更2值 | H5: 变更3生效 (YYYYMM) | I5: 变更3值 | J5: 变更4生效 (YYYYMM) | K5: 变更4值 | L5: 变更5生效 (YYYYMM) | M5: 变更5值
A6: 双方月可支配收入合计 | B6: 26000 | C6: 每月税后可支配收入
A7: 年终奖（合计） | B7: 46000
A8: 当前存款 | B8: 380000 | C8: 截至2026年2月
A9: 婚前月租金 | B9: 2400 | C9: 生育前，含停车费
A10: 生育后月租金 | B10: 3900 | C10: 孩子出生后搬入更大住所，含停车费
A11: 月日常开销 | B11: 1500 | C11: 餐饮/交通/娱乐等
A12: 孩子月开销 | B12: 3000 | C12: 奶粉/纸尿裤/早教等（出生后）
A13: 年度旅游支出 | B13: 15000
A14: 存款年利率 | B14: 0.025 | C14: 按年初余额计算，保守型理财参考收益率
A16: 🏠 买房假设
A17: 参数名 | B17: 初始值 | C17: 备注 | D17: 变更1生效 (YYYYMM) | E17: 变更1值 | F17: 变更2生效 (YYYYMM) | G17: 变更2值 | H17: 变更3生效 (YYYYMM) | I17: 变更3值 | J17: 变更4生效 (YYYYMM) | K17: 变更4值 | L17: 变更5生效 (YYYYMM) | M17: 变更5值
A18: 计划买房时间 | B18: 202801 | C18: YYYYMM格式，如202801=2028年1月
A19: 总房价 | B19: 1500000
A20: 首付比例 | B20: 0.3
A21: 贷款年限 | B21: 30 | C21: 年
A22: 贷款年利率 | B22: 0.031 | C22: 商贷参考利率
A23: 首付金额 | B23: =B19*B20 | C23: 自动计算
A24: 贷款总额 | B24: =B19-B23 | C24: 自动计算
A25: 月供金额 | B25: =-PMT(B22/12,B21*12,B24) | C25: 等额本息，自动计算
A27: 📊 五年收支总览（2026—2030）
B28: 📋 不买房方案 | H28: 🏠 买房方案
A29: 项目 | B29: 2026年 | C29: 2027年 | D29: 2028年 | E29: 2029年 | F29: 2030年 | H29: 2026年 | I29: 2027年 | J29: 2028年 | K29: 2029年 | L29: 2030年
A30: 年初余额 | B30: =$B$8 | C30: =B50 | D30: =C50 | E30: =D50 | F30: =E50 | H30: =$B$8 | I30: =H50 | J30: =I50 | K30: =J50 | L30: =K50
A31: 【收入】
A32: 工资收入 | B32: =SUMIF(月度现金流!B:B,2026,月度现金流!D:D) | C32: =SUMIF(月度现金流!B:B,2027,月度现金流!D:D) | D32: =SUMIF(月度现金流!B:B,2028,月度现金流!D:D) | E32: =SUMIF(月度现金流!B:B,2029,月度现金流!D:D) | F32: =SUMIF(月度现金流!B:B,2030,月度现金流!D:D) | H32: =SUMIF('月度现金流（买房）'!B:B,2026,'月度现金流（买房）'!D:D) | I32: =SUMIF('月度现金流（买房）'!B:B,2027,'月度现金流（买房）'!D:D) | J32: =SUMIF('月度现金流（买房）'!B:B,2028,'月度现金流（买房）'!D:D) | K32: =SUMIF('月度现金流（买房）'!B:B,2029,'月度现金流（买房）'!D:D) | L32: =SUMIF('月度现金流（买房）'!B:B,2030,'月度现金流（买房）'!D:D)
A33: 年终奖 | B33: =SUMIF(月度现金流!B:B,2026,月度现金流!E:E) | C33: =SUMIF(月度现金流!B:B,2027,月度现金流!E:E) | D33: =SUMIF(月度现金流!B:B,2028,月度现金流!E:E) | E33: =SUMIF(月度现金流!B:B,2029,月度现金流!E:E) | F33: =SUMIF(月度现金流!B:B,2030,月度现金流!E:E) | H33: =SUMIF('月度现金流（买房）'!B:B,2026,'月度现金流（买房）'!E:E) | I33: =SUMIF('月度现金流（买房）'!B:B,2027,'月度现金流（买房）'!E:E) | J33: =SUMIF('月度现金流（买房）'!B:B,2028,'月度现金流（买房）'!E:E) | K33: =SUMIF('月度现金流（买房）'!B:B,2029,'月度现金流（买房）'!E:E) | L33: =SUMIF('月度现金流（买房）'!B:B,2030,'月度现金流（买房）'!E:E)
A34: 理财收益 | B34: =SUMIF(月度现金流!B:B,2026,月度现金流!F:F) | C34: =SUMIF(月度现金流!B:B,2027,月度现金流!F:F) | D34: =SUMIF(月度现金流!B:B,2028,月度现金流!F:F) | E34: =SUMIF(月度现金流!B:B,2029,月度现金流!F:F) | F34: =SUMIF(月度现金流!B:B,2030,月度现金流!F:F) | H34: =SUMIF('月度现金流（买房）'!B:B,2026,'月度现金流（买房）'!F:F) | I34: =SUMIF('月度现金流（买房）'!B:B,2027,'月度现金流（买房）'!F:F) | J34: =SUMIF('月度现金流（买房）'!B:B,2028,'月度现金流（买房）'!F:F) | K34: =SUMIF('月度现金流（买房）'!B:B,2029,'月度现金流（买房）'!F:F) | L34: =SUMIF('月度现金流（买房）'!B:B,2030,'月度现金流（买房）'!F:F)
A35: 收入小计 | B35: =SUM(B32:B34) | C35: =SUM(C32:C34) | D35: =SUM(D32:D34) | E35: =SUM(E32:E34) | F35: =SUM(F32:F34) | H35: =SUM(H32:H34) | I35: =SUM(I32:I34) | J35: =SUM(J32:J34) | K35: =SUM(K32:K34) | L35: =SUM(L32:L34)
A36: 【支出】
A37: 房租 | B37: =SUMIF(月度现金流!B:B,2026,月度现金流!H:H) | C37: =SUMIF(月度现金流!B:B,2027,月度现金流!H:H) | D37: =SUMIF(月度现金流!B:B,2028,月度现金流!H:H) | E37: =SUMIF(月度现金流!B:B,2029,月度现金流!H:H) | F37: =SUMIF(月度现金流!B:B,2030,月度现金流!H:H) | H37: =SUMIF('月度现金流（买房）'!B:B,2026,'月度现金流（买房）'!H:H) | I37: =SUMIF('月度现金流（买房）'!B:B,2027,'月度现金流（买房）'!H:H) | J37: =SUMIF('月度现金流（买房）'!B:B,2028,'月度现金流（买房）'!H:H) | K37: =SUMIF('月度现金流（买房）'!B:B,2029,'月度现金流（买房）'!H:H) | L37: =SUMIF('月度现金流（买房）'!B:B,2030,'月度现金流（买房）'!H:H)
A38: 日常开销 | B38: =SUMIF(月度现金流!B:B,2026,月度现金流!I:I) | C38: =SUMIF(月度现金流!B:B,2027,月度现金流!I:I) | D38: =SUMIF(月度现金流!B:B,2028,月度现金流!I:I) | E38: =SUMIF(月度现金流!B:B,2029,月度现金流!I:I) | F38: =SUMIF(月度现金流!B:B,2030,月度现金流!I:I) | H38: =SUMIF('月度现金流（买房）'!B:B,2026,'月度现金流（买房）'!I:I) | I38: =SUMIF('月度现金流（买房）'!B:B,2027,'月度现金流（买房）'!I:I) | J38: =SUMIF('月度现金流（买房）'!B:B,2028,'月度现金流（买房）'!I:I) | K38: =SUMIF('月度现金流（买房）'!B:B,2029,'月度现金流（买房）'!I:I) | L38: =SUMIF('月度现金流（买房）'!B:B,2030,'月度现金流（买房）'!I:I)
A39: 育儿开销 | B39: =SUMIF(月度现金流!B:B,2026,月度现金流!J:J) | C39: =SUMIF(月度现金流!B:B,2027,月度现金流!J:J) | D39: =SUMIF(月度现金流!B:B,2028,月度现金流!J:J) | E39: =SUMIF(月度现金流!B:B,2029,月度现金流!J:J) | F39: =SUMIF(月度现金流!B:B,2030,月度现金流!J:J) | H39: =SUMIF('月度现金流（买房）'!B:B,2026,'月度现金流（买房）'!J:J) | I39: =SUMIF('月度现金流（买房）'!B:B,2027,'月度现金流（买房）'!J:J) | J39: =SUMIF('月度现金流（买房）'!B:B,2028,'月度现金流（买房）'!J:J) | K39: =SUMIF('月度现金流（买房）'!B:B,2029,'月度现金流（买房）'!J:J) | L39: =SUMIF('月度现金流（买房）'!B:B,2030,'月度现金流（买房）'!J:J)
A40: 旅游支出 | B40: =SUMIFS(月度现金流!K:K,月度现金流!B:B,2026,月度现金流!L:L,"年度旅游") | C40: =SUMIFS(月度现金流!K:K,月度现金流!B:B,2027,月度现金流!L:L,"年度旅游") | D40: =SUMIFS(月度现金流!K:K,月度现金流!B:B,2028,月度现金流!L:L,"年度旅游") | E40: =SUMIFS(月度现金流!K:K,月度现金流!B:B,2029,月度现金流!L:L,"年度旅游") | F40: =SUMIFS(月度现金流!K:K,月度现金流!B:B,2030,月度现金流!L:L,"年度旅游") | H40: =SUMIFS('月度现金流（买房）'!K:K,'月度现金流（买房）'!B:B,2026,'月度现金流（买房）'!L:L,"年度旅游") | I40: =SUMIFS('月度现金流（买房）'!K:K,'月度现金流（买房）'!B:B,2027,'月度现金流（买房）'!L:L,"年度旅游") | J40: =SUMIFS('月度现金流（买房）'!K:K,'月度现金流（买房）'!B:B,2028,'月度现金流（买房）'!L:L,"年度旅游") | K40: =SUMIFS('月度现金流（买房）'!K:K,'月度现金流（买房）'!B:B,2029,'月度现金流（买房）'!L:L,"年度旅游") | L40: =SUMIFS('月度现金流（买房）'!K:K,'月度现金流（买房）'!B:B,2030,'月度现金流（买房）'!L:L,"年度旅游")
A41: 首付支出 | H41: =SUMIF('月度现金流（买房）'!B:B,2026,'月度现金流（买房）'!M:M) | I41: =SUMIF('月度现金流（买房）'!B:B,2027,'月度现金流（买房）'!M:M) | J41: =SUMIF('月度现金流（买房）'!B:B,2028,'月度现金流（买房）'!M:M) | K41: =SUMIF('月度现金流（买房）'!B:B,2029,'月度现金流（买房）'!M:M) | L41: =SUMIF('月度现金流（买房）'!B:B,2030,'月度现金流（买房）'!M:M)
A42: 房贷月供 | H42: =SUMIF('月度现金流（买房）'!B:B,2026,'月度现金流（买房）'!N:N) | I42: =SUMIF('月度现金流（买房）'!B:B,2027,'月度现金流（买房）'!N:N) | J42: =SUMIF('月度现金流（买房）'!B:B,2028,'月度现金流（买房）'!N:N) | K42: =SUMIF('月度现金流（买房）'!B:B,2029,'月度现金流（买房）'!N:N) | L42: =SUMIF('月度现金流（买房）'!B:B,2030,'月度现金流（买房）'!N:N)
A43: 【特殊支出】
...

Sheet 月度现金流
A1: 序号 | B1: 年份 | C1: 月份 | D1: 月收入(元) | E1: 年终奖(元) | F1: 理财收益(元) | G1: 总收入(元) | H1: 房租(元) | I1: 日常开销(元) | J1: 孩子开销(元) | K1: 特殊支出(元) | L1: 特殊说明 | M1: 总支出(元) | N1: 当月净储蓄(元) | O1: 累计储蓄(元)
A2: 1 | B2: 2026 | C2: 2月 | D2: =IF(AND(总览!$L$6<>"",B2*100+VALUE(LEFT(C2,LEN(C2)-1))>=总览!$L$6),总览!$M$6,IF(AND(总览!$J$6<>"",B2*100+VALUE(LEFT(C2,LEN(C2)-1))>=总览!$J$6),总览!$K$6,IF(AND(总览!$H$6<>"",B2*100+VALUE(LEFT(C2,LEN(C2)-1))>=总览!$H$6),总览!$I$6,IF(AND(总览!$F$6<>"",B2*100+VALUE(LEFT(C2,LEN(C2)-1))>=总览!$F$6),总览!$G$6,IF(AND(总览!$D$6<>"",B2*100+VALUE(LEFT(C2,LEN(C2)-1))>=总览!$D$6),总览!$E$6,总览!$B$6))))) | E2: =IF(C2="12月",IF(AND(总览!$L$7<>"",B2*100+VALUE(LEFT(C2,LEN(C2)-1))>=总览!$L$7),总览!$M$7,IF(AND(总览!$J$7<>"",B2*100+VALUE(LEFT(C2,LEN(C2)-1))>=总览!$J$7),总览!$K$7,IF(AND(总览!$H$7<>"",B2*100+VALUE(LEFT(C2,LEN(C2)-1))>=总览!$H$7),总览!$I$7,IF(AND(总览!$F$7<>"",B2*100+VALUE(LEFT(C2,LEN(C2)-1))>=总览!$F$7),总览!$G$7,IF(AND(总览!$D$7<>"",B2*100+VALUE(LEFT(C2,LEN(C2)-1))>=总览!$D$7),总览!$E$7,总览!$B$7))))),0) | F2: =ROUND(总览!$B$8*总览!$B$14/12,0) | G2: =D2+E2+F2 | H2: =IF(OR(B2>2027,AND(B2=2027,VALUE(LEFT(C2,LEN(C2)-1))>=9)),IF(AND(总览!$L$10<>"",B2*100+VALUE(LEFT(C2,LEN(C2)-1))>=总览!$L$10),总览!$M$10,IF(AND(总览!$J$10<>"",B2*100+VALUE(LEFT(C2,LEN(C2)-1))>=总览!$J$10),总览!$K$10,IF(AND(总览!$H$10<>"",B2*100+VALUE(LEFT(C2,LEN(C2)-1))>=总览!$H$10),总览!$I$10,IF(AND(总览!$F$10<>"",B2*100+VALUE(LEFT(C2,LEN(C2)-1))>=总览!$F$10),总览!$G$10,IF(AND(总览!$D$10<>"",B2*100+VALUE(LEFT(C2,LEN(C2)-1))>=总览!$D$10),总览!$E$10,总览!$B$10))))),IF(AND(总览!$L$9<>"",B2*100+VALUE(LEFT(C2,LEN(C2)-1))>=总览!$L$9),总览!$M$9,IF(AND(总览!$J$9<>"",B2*100+VALUE(LEFT(C2,LEN(C2)-1))>=总览!$J$9),总览!$K$9,IF(AND(总览!$H$9<>"",B2*100+VALUE(LEFT(C2,LEN(C2)-1))>=总览!$H$9),总览!$I$9,IF(AND(总览!$F$9<>"",B2*100+VALUE(LEFT(C2,LEN(C2)-1))>=总览!$F$9),总览!$G$9,IF(AND(总览!$D$9<>"",B2*100+VALUE(LEFT(C2,LEN(C2)-1))>=总览!$D$9),总览!$E$9,总览!$B$9)))))) | I2: =IF(AND(总览!$L$11<>"",B2*100+VALUE(LEFT(C2,LEN(C2)-1))>=总览!$L$11),总览!$M$11,IF(AND(总览!$J$11<>"",B2*100+VALUE(LEFT(C2,LEN(C2)-1))>=总览!$J$11),总览!$K$11,IF(AND(总览!$H$11<>"",B2*100+VALUE(LEFT(C2,LEN(C2)-1))>=总览!$H$11),总览!$I$11,IF(AND(总览!$F$11<>"",B2*100+VALUE(LEFT(C2,LEN(C2)-1))>=总览!$F$11),总览!$G$11,IF(AND(总览!$D$11<>"",B2*100+VALUE(LEFT(C2,LEN(C2)-1))>=总览!$D$11),总览!$E$11,总览!$B$11))))) | J2: =IF(OR(B2>2027,AND(B2=2027,VALUE(LEFT(C2,LEN(C2)-1))>=9)),IF(AND(总览!$L$12<>"",B2*100+VALUE(LEFT(C2,LEN(C2)-1))>=总览!$L$12),总览!$M$12,IF(AND(总览!$J$12<>"",B2*100+VALUE(LEFT(C2,LEN(C2)-1))>=总览!$J$12),总览!$K$12,IF(AND(总览!$H$12<>"",B2*100+VALUE(LEFT(C2,LEN(C2)-1))>=总览!$H$12),总览!$I$12,IF(AND(总览!$F$12<>"",B2*100+VALUE(LEFT(C2,LEN(C2)-1))>=总览!$F$12),总览!$G$12,IF(AND(总览!$D$12<>"",B2*100+VALUE(LEFT(C2,LEN(C2)-1))>=总览!$D$12),总览!$E$12,总览!$B$12))))),0) | K2: =IF(AND(B2=2026,C2="5月"),120000,IF(AND(B2=2027,C2="9月"),30000,IF(C2="10月",IF(AND(总览!$L$13<>"",B2*100+VALUE(LEFT(C2,LEN(C2)-1))>=总览!$L$13),总览!$M$13,IF(AND(总览!$J$13<>"",B2*100+VALUE(LEFT(C2,LEN(C2)-1))>=总览!$J$13),总览!$K$13,IF(AND(总览!$H$13<>"",B2*100+VALUE(LEFT(C2,LEN(C2)-1))>=总览!$H$13),总览!$I$13,IF(AND(总览!$F$13<>"",B2*100+VALUE(LEFT(C2,LEN(C2)-1))>=总览!$F$13),总览!$G$13,IF(AND(总览!$D$13<>"",B2*100+VALUE(LEFT(C2,LEN(C2)-1))>=总览!$D$13),总览!$E$13,总览!$B$13))))),0))) | M2: =SUM(H2:K2) | N2: =G2-M2 | O2: =总览!$B$8+N2
A3: 2 | B3: 2026 | C3: 3月 | D3: =IF(AND(总览!$L$6<>"",B3*100+VALUE(LEFT(C3,LEN(C3)-1))>=总览!$L$6),总览!$M$6,IF(AND(总览!$J$6<>"",B3*100+VALUE(LEFT(C3,LEN(C3)-1))>=总览!$J$6),总览!$K$6,IF(AND(总览!$H$6<>"",B3*100+VALUE(LEFT(C3,LEN(C3)-1))>=总览!$H$6),总览!$I$6,IF(AND(总览!$F$6<>"",B3*100+VALUE(LEFT(C3,LEN(C3)-1))>=总览!$F$6),总览!$G$6,IF(AND(总览!$D$6<>"",B3*100+VALUE(LEFT(C3,LEN(C3)-1))>=总览!$D$6),总览!$E$6,总览!$B$6))))) | E3: =IF(C3="12月",IF(AND(总览!$L$7<>"",B3*100+VALUE(LEFT(C3,LEN(C3)-1))>=总览!$L$7),总览!$M$7,IF(AND(总览!$J$7<>"",B3*100+VALUE(LEFT(C3,LEN(C3)-1))>=总览!$J$7),总览!$K$7,IF(AND(总览!$H$7<>"",B3*100+VALUE(LEFT(C3,LEN(C3)-1))>=总览!$H$7),总览!$I$7,IF(AND(总览!$F$7<>"",B3*100+VALUE(LEFT(C3,LEN(C3)-1))>=总览!$F$7),总览!$G$7,IF(AND(总览!$D$7<>"",B3*100+VALUE(LEFT(C3,LEN(C3)-1))>=总览!$D$7),总览!$E$7,总览!$B$7))))),0) | F3: =ROUND(O2*总览!$B$14/12,0) | G3: =D3+E3+F3 | H3: =IF(OR(B3>2027,AND(B3=2027,VALUE(LEFT(C3,LEN(C3)-1))>=9)),IF(AND(总览!$L$10<>"",B3*100+VALUE(LEFT(C3,LEN(C3)-1))>=总览!$L$10),总览!$M$10,IF(AND(总览!$J$10<>"",B3*100+VALUE(LEFT(C3,LEN(C3)-1))>=总览!$J$10),总览!$K$10,IF(AND(总览!$H$10<>"",B3*100+VALUE(LEFT(C3,LEN(C3)-1))>=总览!$H$10),总览!$I$10,IF(AND(总览!$F$10<>"",B3*100+VALUE(LEFT(C3,LEN(C3)-1))>=总览!$F$10),总览!$G$10,IF(AND(总览!$D$10<>"",B3*100+VALUE(LEFT(C3,LEN(C3)-1))>=总览!$D$10),总览!$E$10,总览!$B$10))))),IF(AND(总览!$L$9<>"",B3*100+VALUE(LEFT(C3,LEN(C3)-1))>=总览!$L$9),总览!$M$9,IF(AND(总览!$J$9<>"",B3*100+VALUE(LEFT(C3,LEN(C3)-1))>=总览!$J$9),总览!$K$9,IF(AND(总览!$H$9<>"",B3*100+VALUE(LEFT(C3,LEN(C3)-1))>=总览!$H$9),总览!$I$9,IF(AND(总览!$F$9<>"",B3*100+VALUE(LEFT(C3,LEN(C3)-1))>=总览!$F$9),总览!$G$9,IF(AND(总览!$D$9<>"",B3*100+VALUE(LEFT(C3,LEN(C3)-1))>=总览!$D$9),总览!$E$9,总览!$B$9)))))) | I3: =IF(AND(总览!$L$11<>"",B3*100+VALUE(LEFT(C3,LEN(C3)-1))>=总览!$L$11),总览!$M$11,IF(AND(总览!$J$11<>"",B3*100+VALUE(LEFT(C3,LEN(C3)-1))>=总览!$J$11),总览!$K$11,IF(AND(总览!$H$11<>"",B3*100+VALUE(LEFT(C3,LEN(C3)-1))>=总览!$H$11),总览!$I$11,IF(AND(总览!$F$11<>"",B3*100+VALUE(LEFT(C3,LEN(C3)-1))>=总览!$F$11),总览!$G$11,IF(AND(总览!$D$11<>"",B3*100+VALUE(LEFT(C3,LEN(C3)-1))>=总览!$D$11),总览!$E$11,总览!$B$11))))) | J3: =IF(OR(B3>2027,AND(B3=2027,VALUE(LEFT(C3,LEN(C3)-1))>=9)),IF(AND(总览!$L$12<>"",B3*100+VALUE(LEFT(C3,LEN(C3)-1))>=总览!$L$12),总览!$M$12,IF(AND(总览!$J$12<>"",B3*100+VALUE(LEFT(C3,LEN(C3)-1))>=总览!$J$12),总览!$K$12,IF(AND(总览!$H$12<>"",B3*100+VALUE(LEFT(C3,LEN(C3)-1))>=总览!$H$12),总览!$I$12,IF(AND(总览!$F$12<>"",B3*100+VALUE(LEFT(C3,LEN(C3)-1))>=总览!$F$12),总览!$G$12,IF(AND(总览!$D$12<>"",B3*100+VALUE(LEFT(C3,LEN(C3)-1))>=总览!$D$12),总览!$E$12,总览!$B$12))))),0) | K3: =IF(AND(B3=2026,C3="5月"),120000,IF(AND(B3=2027,C3="9月"),30000,IF(C3="10月",IF(AND(总览!$L$13<>"",B3*100+VALUE(LEFT(C3,LEN(C3)-1))>=总览!$L$13),总览!$M$13,IF(AND(总览!$J$13<>"",B3*100+VALUE(LEFT(C3,LEN(C3)-1))>=总览!$J$13),总览!$K$13,IF(AND(总览!$H$13<>"",B3*100+VALUE(LEFT(C3,LEN(C3)-1))>=总览!$H$13),总览!$I$13,IF(AND(总览!$F$13<>"",B3*100+VALUE(LEFT(C3,LEN(C3)-1))>=总览!$F$13),总览!$G$13,IF(AND(总览!$D$13<>"",B3*100+VALUE(LEFT(C3,LEN(C3)-1))>=总览!$D$13),总览!$E$13,总览!$B$13))))),0))) | M3: =SUM(H3:K3) | N3: =G3-M3 | O3: =O2+N3
A4: 3 | B4: 2026 | C4: 4月 | D4: =IF(AND(总览!$L$6<>"",B4*100+VALUE(LEFT(C4,LEN(C4)-1))>=总览!$L$6),总览!$M$6,IF(AND(总览!$J$6<>"",B4*100+VALUE(LEFT(C4,LEN(C4)-1))>=总览!$J$6),总览!$K$6,IF(AND(总览!$H$6<>"",B4*100+VALUE(LEFT(C4,LEN(C4)-1))>=总览!$H$6),总览!$I$6,IF(AND(总览!$F$6<>"",B4*100+VALUE(LEFT(C4,LEN(C4)-1))>=总览!$F$6),总览!$G$6,IF(AND(总览!$D$6<>"",B4*100+VALUE(LEFT(C4,LEN(C4)-1))>=总览!$D$6),总览!$E$6,总览!$B$6))))) | E4: =IF(C4="12月",IF(AND(总览!$L$7<>"",B4*100+VALUE(LEFT(C4,LEN(C4)-1))>=总览!$L$7),总览!$M$7,IF(AND(总览!$J$7<>"",B4*100+VALUE(LEFT(C4,LEN(C4)-1))>=总览!$J$7),总览!$K$7,IF(AND(总览!$H$7<>"",B4*100+VALUE(LEFT(C4,LEN(C4)-1))>=总览!$H$7),总览!$I$7,IF(AND(总览!$F$7<>"",B4*100+VALUE(LEFT(C4,LEN(C4)-1))>=总览!$F$7),总览!$G$7,IF(AND(总览!$D$7<>"",B4*100+VALUE(LEFT(C4,LEN(C4)-1))>=总览!$D$7),总览!$E$7,总览!$B$7))))),0) | F4: =ROUND(O3*总览!$B$14/12,0) | G4: =D4+E4+F4 | H4: =IF(OR(B4>2027,AND(B4=2027,VALUE(LEFT(C4,LEN(C4)-1))>=9)),IF(AND(总览!$L$10<>"",B4*100+VALUE(LEFT(C4,LEN(C4)-1))>=总览!$L$10),总览!$M$10,IF(AND(总览!$J$10<>"",B4*100+VALUE(LEFT(C4,LEN(C4)-1))>=总览!$J$10),总览!$K$10,IF(AND(总览!$H$10<>"",B4*100+VALUE(LEFT(C4,LEN(C4)-1))>=总览!$H$10),总览!$I$10,IF(AND(总览!$F$10<>"",B4*100+VALUE(LEFT(C4,LEN(C4)-1))>=总览!$F$10),总览!$G$10,IF(AND(总览!$D$10<>"",B4*100+VALUE(LEFT(C4,LEN(C4)-1))>=总览!$D$10),总览!$E$10,总览!$B$10))))),IF(AND(总览!$L$9<>"",B4*100+VALUE(LEFT(C4,LEN(C4)-1))>=总览!$L$9),总览!$M$9,IF(AND(总览!$J$9<>"",B4*100+VALUE(LEFT(C4,LEN(C4)-1))>=总览!$J$9),总览!$K$9,IF(AND(总览!$H$9<>"",B4*100+VALUE(LEFT(C4,LEN(C4)-1))>=总览!$H$9),总览!$I$9,IF(AND(总览!$F$9<>"",B4*100+VALUE(LEFT(C4,LEN(C4)-1))>=总览!$F$9),总览!$G$9,IF(AND(总览!$D$9<>"",B4*100+VALUE(LEFT(C4,LEN(C4)-1))>=总览!$D$9),总览!$E$9,总览!$B$9)))))) | I4: =IF(AND(总览!$L$11<>"",B4*100+VALUE(LEFT(C4,LEN(C4)-1))>=总览!$L$11),总览!$M$11,IF(AND(总览!$J$11<>"",B4*100+VALUE(LEFT(C4,LEN(C4)-1))>=总览!$J$11),总览!$K$11,IF(AND(总览!$H$11<>"",B4*100+VALUE(LEFT(C4,LEN(C4)-1))>=总览!$H$11),总览!$I$11,IF(AND(总览!$F$11<>"",B4*100+VALUE(LEFT(C4,LEN(C4)-1))>=总览!$F$11),总览!$G$11,IF(AND(总览!$D$11<>"",B4*100+VALUE(LEFT(C4,LEN(C4)-1))>=总览!$D$11),总览!$E$11,总览!$B$11))))) | J4: =IF(OR(B4>2027,AND(B4=2027,VALUE(LEFT(C4,LEN(C4)-1))>=9)),IF(AND(总览!$L$12<>"",B4*100+VALUE(LEFT(C4,LEN(C4)-1))>=总览!$L$12),总览!$M$12,IF(AND(总览!$J$12<>"",B4*100+VALUE(LEFT(C4,LEN(C4)-1))>=总览!$J$12),总览!$K$12,IF(AND(总览!$H$12<>"",B4*100+VALUE(LEFT(C4,LEN(C4)-1))>=总览!$H$12),总览!$I$12,IF(AND(总览!$F$12<>"",B4*100+VALUE(LEFT(C4,LEN(C4)-1))>=总览!$F$12),总览!$G$12,IF(AND(总览!$D$12<>"",B4*100+VALUE(LEFT(C4,LEN(C4)-1))>=总览!$D$12),总览!$E$12,总览!$B$12))))),0) | K4: =IF(AND(B4=2026,C4="5月"),120000,IF(AND(B4=2027,C4="9月"),30000,IF(C4="10月",IF(AND(总览!$L$13<>"",B4*100+VALUE(LEFT(C4,LEN(C4)-1))>=总览!$L$13),总览!$M$13,IF(AND(总览!$J$13<>"",B4*100+VALUE(LEFT(C4,LEN(C4)-1))>=总览!$J$13),总览!$K$13,IF(AND(总览!$H$13<>"",B4*100+VALUE(LEFT(C4,LEN(C4)-1))>=总览!$H$13),总览!$I$13,IF(AND(总览!$F$13<>"",B4*100+VALUE(LEFT(C4,LEN(C4)-1))>=总览!$F$13),总览!$G$13,IF(AND(总览!$D$13<>"",B4*100+VALUE(LEFT(C4,LEN(C4)-1))>=总览!$D$13),总览!$E$13,总览!$B$13))))),0))) | M4: =SUM(H4:K4) | N4: =G4-M4 | O4: =O3+N4
A5: 4 | B5: 2026 | C5: 5月 | D5: =IF(AND(总览!$L$6<>"",B5*100+VALUE(LEFT(C5,LEN(C5)-1))>=总览!$L$6),总览!$M$6,IF(AND(总览!$J$6<>"",B5*100+VALUE(LEFT(C5,LEN(C5)-1))>=总览!$J$6),总览!$K$6,IF(AND(总览!$H$6<>"",B5*100+VALUE(LEFT(C5,LEN(C5)-1))>=总览!$H$6),总览!$I$6,IF(AND(总览!$F$6<>"",B5*100+VALUE(LEFT(C5,LEN(C5)-1))>=总览!$F$6),总览!$G$6,IF(AND(总览!$D$6<>"",B5*100+VALUE(LEFT(C5,LEN(C5)-1))>=总览!$D$6),总览!$E$6,总览!$B$6))))) | E5: =IF(C5="12月",IF(AND(总览!$L$7<>"",B5*100+VALUE(LEFT(C5,LEN(C5)-1))>=总览!$L$7),总览!$M$7,IF(AND(总览!$J$7<>"",B5*100+VALUE(LEFT(C5,LEN(C5)-1))>=总览!$J$7),总览!$K$7,IF(AND(总览!$H$7<>"",B5*100+VALUE(LEFT(C5,LEN(C5)-1))>=总览!$H$7),总览!$I$7,IF(AND(总览!$F$7<>"",B5*100+VALUE(LEFT(C5,LEN(C5)-1))>=总览!$F$7),总览!$G$7,IF(AND(总览!$D$7<>"",B5*100+VALUE(LEFT(C5,LEN(C5)-1))>=总览!$D$7),总览!$E$7,总览!$B$7))))),0) | F5: =ROUND(O4*总览!$B$14/12,0) | G5: =D5+E5+F5 | H5: =IF(OR(B5>2027,AND(B5=2027,VALUE(LEFT(C5,LEN(C5)-1))>=9)),IF(AND(总览!$L$10<>"",B5*100+VALUE(LEFT(C5,LEN(C5)-1))>=总览!$L$10),总览!$M$10,IF(AND(总览!$J$10<>"",B5*100+VALUE(LEFT(C5,LEN(C5)-1))>=总览!$J$10),总览!$K$10,IF(AND(总览!$H$10<>"",B5*100+VALUE(LEFT(C5,LEN(C5)-1))>=总览!$H$10),总览!$I$10,IF(AND(总览!$F$10<>"",B5*100+VALUE(LEFT(C5,LEN(C5)-1))>=总览!$F$10),总览!$G$10,IF(AND(总览!$D$10<>"",B5*100+VALUE(LEFT(C5,LEN(C5)-1))>=总览!$D$10),总览!$E$10,总览!$B$10))))),IF(AND(总览!$L$9<>"",B5*100+VALUE(LEFT(C5,LEN(C5)-1))>=总览!$L$9),总览!$M$9,IF(AND(总览!$J$9<>"",B5*100+VALUE(LEFT(C5,LEN(C5)-1))>=总览!$J$9),总览!$K$9,IF(AND(总览!$H$9<>"",B5*100+VALUE(LEFT(C5,LEN(C5)-1))>=总览!$H$9),总览!$I$9,IF(AND(总览!$F$9<>"",B5*100+VALUE(LEFT(C5,LEN(C5)-1))>=总览!$F$9),总览!$G$9,IF(AND(总览!$D$9<>"",B5*100+VALUE(LEFT(C5,LEN(C5)-1))>=总览!$D$9),总览!$E$9,总览!$B$9)))))) | I5: =IF(AND(总览!$L$11<>"",B5*100+VALUE(LEFT(C5,LEN(C5)-1))>=总览!$L$11),总览!$M$11,IF(AND(总览!$J$11<>"",B5*100+VALUE(LEFT(C5,LEN(C5)-1))>=总览!$J$11),总览!$K$11,IF(AND(总览!$H$11<>"",B5*100+VALUE(LEFT(C5,LEN(C5)-1))>=总览!$H$11),总览!$I$11,IF(AND(总览!$F$11<>"",B5*100+VALUE(LEFT(C5,LEN(C5)-1))>=总览!$F$11),总览!$G$11,IF(AND(总览!$D$11<>"",B5*100+VALUE(LEFT(C5,LEN(C5)-1))>=总览!$D$11),总览!$E$11,总览!$B$11))))) | J5: =IF(OR(B5>2027,AND(B5=2027,VALUE(LEFT(C5,LEN(C5)-1))>=9)),IF(AND(总览!$L$12<>"",B5*100+VALUE(LEFT(C5,LEN(C5)-1))>=总览!$L$12),总览!$M$12,IF(AND(总览!$J$12<>"",B5*100+VALUE(LEFT(C5,LEN(C5)-1))>=总览!$J$12),总览!$K$12,IF(AND(总览!$H$12<>"",B5*100+VALUE(LEFT(C5,LEN(C5)-1))>=总览!$H$12),总览!$I$12,IF(AND(总览!$F$12<>"",B5*100+VALUE(LEFT(C5,LEN(C5)-1))>=总览!$F$12),总览!$G$12,IF(AND(总览!$D$12<>"",B5*100+VALUE(LEFT(C5,LEN(C5)-1))>=总览!$D$12),总览!$E$12,总览!$B$12))))),0) | K5: =IF(AND(B5=2026,C5="5月"),120000,IF(AND(B5=2027,C5="9月"),30000,IF(C5="10月",IF(AND(总览!$L$13<>"",B5*100+VALUE(LEFT(C5,LEN(C5)-1))>=总览!$L$13),总览!$M$13,IF(AND(总览!$J$13<>"",B5*100+VALUE(LEFT(C5,LEN(C5)-1))>=总览!$J$13),总览!$K$13,IF(AND(总览!$H$13<>"",B5*100+VALUE(LEFT(C5,LEN(C5)-1))>=总览!$H$13),总览!$I$13,IF(AND(总览!$F$13<>"",B5*100+VALUE(LEFT(C5,LEN(C5)-1))>=总览!$F$13),总览!$G$13,IF(AND(总览!$D$13<>"",B5*100+VALUE(LEFT(C5,LEN(C5)-1))>=总览!$D$13),总览!$E$13,总览!$B$13))))),0))) | L5: 结婚支出 | M5: =SUM(H5:K5) | N5: =G5-M5 | O5: =O4+N5
A6: 5 | B6: 2026 | C6: 6月 | D6: =IF(AND(总览!$L$6<>"",B6*100+VALUE(LEFT(C6,LEN(C6)-1))>=总览!$L$6),总览!$M$6,IF(AND(总览!$J$6<>"",B6*100+VALUE(LEFT(C6,LEN(C6)-1))>=总览!$J$6),总览!$K$6,IF(AND(总览!$H$6<>"",B6*100+VALUE(LEFT(C6,LEN(C6)-1))>=总览!$H$6),总览!$I$6,IF(AND(总览!$F$6<>"",B6*100+VALUE(LEFT(C6,LEN(C6)-1))>=总览!$F$6),总览!$G$6,IF(AND(总览!$D$6<>"",B6*100+VALUE(LEFT(C6,LEN(C6)-1))>=总览!$D$6),总览!$E$6,总览!$B$6))))) | E6: =IF(C6="12月",IF(AND(总览!$L$7<>"",B6*100+VALUE(LEFT(C6,LEN(C6)-1))>=总览!$L$7),总览!$M$7,IF(AND(总览!$J$7<>"",B6*100+VALUE(LEFT(C6,LEN(C6)-1))>=总览!$J$7),总览!$K$7,IF(AND(总览!$H$7<>"",B6*100+VALUE(LEFT(C6,LEN(C6)-1))>=总览!$H$7),总览!$I$7,IF(AND(总览!$F$7<>"",B6*100+VALUE(LEFT(C6,LEN(C6)-1))>=总览!$F$7),总览!$G$7,IF(AND(总览!$D$7<>"",B6*100+VALUE(LEFT(C6,LEN(C6)-1))>=总览!$D$7),总览!$E$7,总览!$B$7))))),0) | F6: =ROUND(O5*总览!$B$14/12,0) | G6: =D6+E6+F6 | H6: =IF(OR(B6>2027,AND(B6=2027,VALUE(LEFT(C6,LEN(C6)-1))>=9)),IF(AND(总览!$L$10<>"",B6*100+VALUE(LEFT(C6,LEN(C6)-1))>=总览!$L$10),总览!$M$10,IF(AND(总览!$J$10<>"",B6*100+VALUE(LEFT(C6,LEN(C6)-1))>=总览!$J$10),总览!$K$10,IF(AND(总览!$H$10<>"",B6*100+VALUE(LEFT(C6,LEN(C6)-1))>=总览!$H$10),总览!$I$10,IF(AND(总览!$F$10<>"",B6*100+VALUE(LEFT(C6,LEN(C6)-1))>=总览!$F$10),总览!$G$10,IF(AND(总览!$D$10<>"",B6*100+VALUE(LEFT(C6,LEN(C6)-1))>=总览!$D$10),总览!$E$10,总览!$B$10))))),IF(AND(总览!$L$9<>"",B6*100+VALUE(LEFT(C6,LEN(C6)-1))>=总览!$L$9),总览!$M$9,IF(AND(总览!$J$9<>"",B6*100+VALUE(LEFT(C6,LEN(C6)-1))>=总览!$J$9),总览!$K$9,IF(AND(总览!$H$9<>"",B6*100+VALUE(LEFT(C6,LEN(C6)-1))>=总览!$H$9),总览!$I$9,IF(AND(总览!$F$9<>"",B6*100+VALUE(LEFT(C6,LEN(C6)-1))>=总览!$F$9),总览!$G$9,IF(AND(总览!$D$9<>"",B6*100+VALUE(LEFT(C6,LEN(C6)-1))>=总览!$D$9),总览!$E$9,总览!$B$9)))))) | I6: =IF(AND(总览!$L$11<>"",B6*100+VALUE(LEFT(C6,LEN(C6)-1))>=总览!$L$11),总览!$M$11,IF(AND(总览!$J$11<>"",B6*100+VALUE(LEFT(C6,LEN(C6)-1))>=总览!$J$11),总览!$K$11,IF(AND(总览!$H$11<>"",B6*100+VALUE(LEFT(C6,LEN(C6)-1))>=总览!$H$11),总览!$I$11,IF(AND(总览!$F$11<>"",B6*100+VALUE(LEFT(C6,LEN(C6)-1))>=总览!$F$11),总览!$G$11,IF(AND(总览!$D$11<>"",B6*100+VALUE(LEFT(C6,LEN(C6)-1))>=总览!$D$11),总览!$E$11,总览!$B$11))))) | J6: =IF(OR(B6>2027,AND(B6=2027,VALUE(LEFT(C6,LEN(C6)-1))>=9)),IF(AND(总览!$L$12<>"",B6*100+VALUE(LEFT(C6,LEN(C6)-1))>=总览!$L$12),总览!$M$12,IF(AND(总览!$J$12<>"",B6*100+VALUE(LEFT(C6,LEN(C6)-1))>=总览!$J$12),总览!$K$12,IF(AND(总览!$H$12<>"",B6*100+VALUE(LEFT(C6,LEN(C6)-1))>=总览!$H$12),总览!$I$12,IF(AND(总览!$F$12<>"",B6*100+VALUE(LEFT(C6,LEN(C6)-1))>=总览!$F$12),总览!$G$12,IF(AND(总览!$D$12<>"",B6*100+VALUE(LEFT(C6,LEN(C6)-1))>=总览!$D$12),总览!$E$12,总览!$B$12))))),0) | K6: =IF(AND(B6=2026,C6="5月"),120000,IF(AND(B6=2027,C6="9月"),30000,IF(C6="10月",IF(AND(总览!$L$13<>"",B6*100+VALUE(LEFT(C6,LEN(C6)-1))>=总览!$L$13),总览!$M$13,IF(AND(总览!$J$13<>"",B6*100+VALUE(LEFT(C6,LEN(C6)-1))>=总览!$J$13),总览!$K$13,IF(AND(总览!$H$13<>"",B6*100+VALUE(LEFT(C6,LEN(C6)-1))>=总览!$H$13),总览!$I$13,IF(AND(总览!$F$13<>"",B6*100+VALUE(LEFT(C6,LEN(C6)-1))>=总览!$F$13),总览!$G$13,IF(AND(总览!$D$13<>"",B6*100+VALUE(LEFT(C6,LEN(C6)-1))>=总览!$D$13),总览!$E$13,总览!$B$13))))),0))) | M6: =SUM(H6:K6) | N6: =G6-M6 | O6: =O5+N6
A7: 6 | B7: 2026 | C7: 7月 | D7: =IF(AND(总览!$L$6<>"",B7*100+VALUE(LEFT(C7,LEN(C7)-1))>=总览!$L$6),总览!$M$6,IF(AND(总览!$J$6<>"",B7*100+VALUE(LEFT(C7,LEN(C7)-1))>=总览!$J$6),总览!$K$6,IF(AND(总览!$H$6<>"",B7*100+VALUE(LEFT(C7,LEN(C7)-1))>=总览!$H$6),总览!$I$6,IF(AND(总览!$F$6<>"",B7*100+VALUE(LEFT(C7,LEN(C7)-1))>=总览!$F$6),总览!$G$6,IF(AND(总览!$D$6<>"",B7*100+VALUE(LEFT(C7,LEN(C7)-1))>=总览!$D$6),总览!$E$6,总览!$B$6))))) | E7: =IF(C7="12月",IF(AND(总览!$L$7<>"",B7*100+VALUE(LEFT(C7,LEN(C7)-1))>=总览!$L$7),总览!$M$7,IF(AND(总览!$J$7<>"",B7*100+VALUE(LEFT(C7,LEN(C7)-1))>=总览!$J$7),总览!$K$7,IF(AND(总览!$H$7<>"",B7*100+VALUE(LEFT(C7,LEN(C7)-1))>=总览!$H$7),总览!$I$7,IF(AND(总览!$F$7<>"",B7*100+VALUE(LEFT(C7,LEN(C7)-1))>=总览!$F$7),总览!$G$7,IF(AND(总览!$D$7<>"",B7*100+VALUE(LEFT(C7,LEN(C7)-1))>=总览!$D$7),总览!$E$7,总览!$B$7))))),0) | F7: =ROUND(O6*总览!$B$14/12,0) | G7: =D7+E7+F7 | H7: =IF(OR(B7>2027,AND(B7=2027,VALUE(LEFT(C7,LEN(C7)-1))>=9)),IF(AND(总览!$L$10<>"",B7*100+VALUE(LEFT(C7,LEN(C7)-1))>=总览!$L$10),总览!$M$10,IF(AND(总览!$J$10<>"",B7*100+VALUE(LEFT(C7,LEN(C7)-1))>=总览!$J$10),总览!$K$10,IF(AND(总览!$H$10<>"",B7*100+VALUE(LEFT(C7,LEN(C7)-1))>=总览!$H$10),总览!$I$10,IF(AND(总览!$F$10<>"",B7*100+VALUE(LEFT(C7,LEN(C7)-1))>=总览!$F$10),总览!$G$10,IF(AND(总览!$D$10<>"",B7*100+VALUE(LEFT(C7,LEN(C7)-1))>=总览!$D$10),总览!$E$10,总览!$B$10))))),IF(AND(总览!$L$9<>"",B7*100+VALUE(LEFT(C7,LEN(C7)-1))>=总览!$L$9),总览!$M$9,IF(AND(总览!$J$9<>"",B7*100+VALUE(LEFT(C7,LEN(C7)-1))>=总览!$J$9),总览!$K$9,IF(AND(总览!$H$9<>"",B7*100+VALUE(LEFT(C7,LEN(C7)-1))>=总览!$H$9),总览!$I$9,IF(AND(总览!$F$9<>"",B7*100+VALUE(LEFT(C7,LEN(C7)-1))>=总览!$F$9),总览!$G$9,IF(AND(总览!$D$9<>"",B7*100+VALUE(LEFT(C7,LEN(C7)-1))>=总览!$D$9),总览!$E$9,总览!$B$9)))))) | I7: =IF(AND(总览!$L$11<>"",B7*100+VALUE(LEFT(C7,LEN(C7)-1))>=总览!$L$11),总览!$M$11,IF(AND(总览!$J$11<>"",B7*100+VALUE(LEFT(C7,LEN(C7)-1))>=总览!$J$11),总览!$K$11,IF(AND(总览!$H$11<>"",B7*100+VALUE(LEFT(C7,LEN(C7)-1))>=总览!$H$11),总览!$I$11,IF(AND(总览!$F$11<>"",B7*100+VALUE(LEFT(C7,LEN(C7)-1))>=总览!$F$11),总览!$G$11,IF(AND(总览!$D$11<>"",B7*100+VALUE(LEFT(C7,LEN(C7)-1))>=总览!$D$11),总览!$E$11,总览!$B$11))))) | J7: =IF(OR(B7>2027,AND(B7=2027,VALUE(LEFT(C7,LEN(C7)-1))>=9)),IF(AND(总览!$L$12<>"",B7*100+VALUE(LEFT(C7,LEN(C7)-1))>=总览!$L$12),总览!$M$12,IF(AND(总览!$J$12<>"",B7*100+VALUE(LEFT(C7,LEN(C7)-1))>=总览!$J$12),总览!$K$12,IF(AND(总览!$H$12<>"",B7*100+VALUE(LEFT(C7,LEN(C7)-1))>=总览!$H$12),总览!$I$12,IF(AND(总览!$F$12<>"",B7*100+VALUE(LEFT(C7,LEN(C7)-1))>=总览!$F$12),总览!$G$12,IF(AND(总览!$D$12<>"",B7*100+VALUE(LEFT(C7,LEN(C7)-1))>=总览!$D$12),总览!$E$12,总览!$B$12))))),0) | K7: =IF(AND(B7=2026,C7="5月"),120000,IF(AND(B7=2027,C7="9月"),30000,IF(C7="10月",IF(AND(总览!$L$13<>"",B7*100+VALUE(LEFT(C7,LEN(C7)-1))>=总览!$L$13),总览!$M$13,IF(AND(总览!$J$13<>"",B7*100+VALUE(LEFT(C7,LEN(C7)-1))>=总览!$J$13),总览!$K$13,IF(AND(总览!$H$13<>"",B7*100+VALUE(LEFT(C7,LEN(C7)-1))>=总览!$H$13),总览!$I$13,IF(AND(总览!$F$13<>"",B7*100+VALUE(LEFT(C7,LEN(C7)-1))>=总览!$F$13),总览!$G$13,IF(AND(总览!$D$13<>"",B7*100+VALUE(LEFT(C7,LEN(C7)-1))>=总览!$D$13),总览!$E$13,总览!$B$13))))),0))) | M7: =SUM(H7:K7) | N7: =G7-M7 | O7: =O6+N7
A8: 7 | B8: 2026 | C8: 8月 | D8: =IF(AND(总览!$L$6<>"",B8*100+VALUE(LEFT(C8,LEN(C8)-1))>=总览!$L$6),总览!$M$6,IF(AND(总览!$J$6<>"",B8*100+VALUE(LEFT(C8,LEN(C8)-1))>=总览!$J$6),总览!$K$6,IF(AND(总览!$H$6<>"",B8*100+VALUE(LEFT(C8,LEN(C8)-1))>=总览!$H$6),总览!$I$6,IF(AND(总览!$F$6<>"",B8*100+VALUE(LEFT(C8,LEN(C8)-1))>=总览!$F$6),总览!$G$6,IF(AND(总览!$D$6<>"",B8*100+VALUE(LEFT(C8,LEN(C8)-1))>=总览!$D$6),总览!$E$6,总览!$B$6))))) | E8: =IF(C8="12月",IF(AND(总览!$L$7<>"",B8*100+VALUE(LEFT(C8,LEN(C8)-1))>=总览!$L$7),总览!$M$7,IF(AND(总览!$J$7<>"",B8*100+VALUE(LEFT(C8,LEN(C8)-1))>=总览!$J$7),总览!$K$7,IF(AND(总览!$H$7<>"",B8*100+VALUE(LEFT(C8,LEN(C8)-1))>=总览!$H$7),总览!$I$7,IF(AND(总览!$F$7<>"",B8*100+VALUE(LEFT(C8,LEN(C8)-1))>=总览!$F$7),总览!$G$7,IF(AND(总览!$D$7<>"",B8*100+VALUE(LEFT(C8,LEN(C8)-1))>=总览!$D$7),总览!$E$7,总览!$B$7))))),0) | F8: =ROUND(O7*总览!$B$14/12,0) | G8: =D8+E8+F8 | H8: =IF(OR(B8>2027,AND(B8=2027,VALUE(LEFT(C8,LEN(C8)-1))>=9)),IF(AND(总览!$L$10<>"",B8*100+VALUE(LEFT(C8,LEN(C8)-1))>=总览!$L$10),总览!$M$10,IF(AND(总览!$J$10<>"",B8*100+VALUE(LEFT(C8,LEN(C8)-1))>=总览!$J$10),总览!$K$10,IF(AND(总览!$H$10<>"",B8*100+VALUE(LEFT(C8,LEN(C8)-1))>=总览!$H$10),总览!$I$10,IF(AND(总览!$F$10<>"",B8*100+VALUE(LEFT(C8,LEN(C8)-1))>=总览!$F$10),总览!$G$10,IF(AND(总览!$D$10<>"",B8*100+VALUE(LEFT(C8,LEN(C8)-1))>=总览!$D$10),总览!$E$10,总览!$B$10))))),IF(AND(总览!$L$9<>"",B8*100+VALUE(LEFT(C8,LEN(C8)-1))>=总览!$L$9),总览!$M$9,IF(AND(总览!$J$9<>"",B8*100+VALUE(LEFT(C8,LEN(C8)-1))>=总览!$J$9),总览!$K$9,IF(AND(总览!$H$9<>"",B8*100+VALUE(LEFT(C8,LEN(C8)-1))>=总览!$H$9),总览!$I$9,IF(AND(总览!$F$9<>"",B8*100+VALUE(LEFT(C8,LEN(C8)-1))>=总览!$F$9),总览!$G$9,IF(AND(总览!$D$9<>"",B8*100+VALUE(LEFT(C8,LEN(C8)-1))>=总览!$D$9),总览!$E$9,总览!$B$9)))))) | I8: =IF(AND(总览!$L$11<>"",B8*100+VALUE(LEFT(C8,LEN(C8)-1))>=总览!$L$11),总览!$M$11,IF(AND(总览!$J$11<>"",B8*100+VALUE(LEFT(C8,LEN(C8)-1))>=总览!$J$11),总览!$K$11,IF(AND(总览!$H$11<>"",B8*100+VALUE(LEFT(C8,LEN(C8)-1))>=总览!$H$11),总览!$I$11,IF(AND(总览!$F$11<>"",B8*100+VALUE(LEFT(C8,LEN(C8)-1))>=总览!$F$11),总览!$G$11,IF(AND(总览!$D$11<>"",B8*100+VALUE(LEFT(C8,LEN(C8)-1))>=总览!$D$11),总览!$E$11,总览!$B$11))))) | J8: =IF(OR(B8>2027,AND(B8=2027,VALUE(LEFT(C8,LEN(C8)-1))>=9)),IF(AND(总览!$L$12<>"",B8*100+VALUE(LEFT(C8,LEN(C8)-1))>=总览!$L$12),总览!$M$12,IF(AND(总览!$J$12<>"",B8*100+VALUE(LEFT(C8,LEN(C8)-1))>=总览!$J$12),总览!$K$12,IF(AND(总览!$H$12<>"",B8*100+VALUE(LEFT(C8,LEN(C8)-1))>=总览!$H$12),总览!$I$12,IF(AND(总览!$F$12<>"",B8*100+VALUE(LEFT(C8,LEN(C8)-1))>=总览!$F$12),总览!$G$12,IF(AND(总览!$D$12<>"",B8*100+VALUE(LEFT(C8,LEN(C8)-1))>=总览!$D$12),总览!$E$12,总览!$B$12))))),0) | K8: =IF(AND(B8=2026,C8="5月"),120000,IF(AND(B8=2027,C8="9月"),30000,IF(C8="10月",IF(AND(总览!$L$13<>"",B8*100+VALUE(LEFT(C8,LEN(C8)-1))>=总览!$L$13),总览!$M$13,IF(AND(总览!$J$13<>"",B8*100+VALUE(LEFT(C8,LEN(C8)-1))>=总览!$J$13),总览!$K$13,IF(AND(总览!$H$13<>"",B8*100+VALUE(LEFT(C8,LEN(C8)-1))>=总览!$H$13),总览!$I$13,IF(AND(总览!$F$13<>"",B8*100+VALUE(LEFT(C8,LEN(C8)-1))>=总览!$F$13),总览!$G$13,IF(AND(总览!$D$13<>"",B8*100+VALUE(LEFT(C8,LEN(C8)-1))>=总览!$D$13),总览!$E$13,总览!$B$13))))),0))) | M8: =SUM(H8:K8) | N8: =G8-M8 | O8: =O7+N8
A9: 8 | B9: 2026 | C9: 9月 | D9: =IF(AND(总览!$L$6<>"",B9*100+VALUE(LEFT(C9,LEN(C9)-1))>=总览!$L$6),总览!$M$6,IF(AND(总览!$J$6<>"",B9*100+VALUE(LEFT(C9,LEN(C9)-1))>=总览!$J$6),总览!$K$6,IF(AND(总览!$H$6<>"",B9*100+VALUE(LEFT(C9,LEN(C9)-1))>=总览!$H$6),总览!$I$6,IF(AND(总览!$F$6<>"",B9*100+VALUE(LEFT(C9,LEN(C9)-1))>=总览!$F$6),总览!$G$6,IF(AND(总览!$D$6<>"",B9*100+VALUE(LEFT(C9,LEN(C9)-1))>=总览!$D$6),总览!$E$6,总览!$B$6))))) | E9: =IF(C9="12月",IF(AND(总览!$L$7<>"",B9*100+VALUE(LEFT(C9,LEN(C9)-1))>=总览!$L$7),总览!$M$7,IF(AND(总览!$J$7<>"",B9*100+VALUE(LEFT(C9,LEN(C9)-1))>=总览!$J$7),总览!$K$7,IF(AND(总览!$H$7<>"",B9*100+VALUE(LEFT(C9,LEN(C9)-1))>=总览!$H$7),总览!$I$7,IF(AND(总览!$F$7<>"",B9*100+VALUE(LEFT(C9,LEN(C9)-1))>=总览!$F$7),总览!$G$7,IF(AND(总览!$D$7<>"",B9*100+VALUE(LEFT(C9,LEN(C9)-1))>=总览!$D$7),总览!$E$7,总览!$B$7))))),0) | F9: =ROUND(O8*总览!$B$14/12,0) | G9: =D9+E9+F9 | H9: =IF(OR(B9>2027,AND(B9=2027,VALUE(LEFT(C9,LEN(C9)-1))>=9)),IF(AND(总览!$L$10<>"",B9*100+VALUE(LEFT(C9,LEN(C9)-1))>=总览!$L$10),总览!$M$10,IF(AND(总览!$J$10<>"",B9*100+VALUE(LEFT(C9,LEN(C9)-1))>=总览!$J$10),总览!$K$10,IF(AND(总览!$H$10<>"",B9*100+VALUE(LEFT(C9,LEN(C9)-1))>=总览!$H$10),总览!$I$10,IF(AND(总览!$F$10<>"",B9*100+VALUE(LEFT(C9,LEN(C9)-1))>=总览!$F$10),总览!$G$10,IF(AND(总览!$D$10<>"",B9*100+VALUE(LEFT(C9,LEN(C9)-1))>=总览!$D$10),总览!$E$10,总览!$B$10))))),IF(AND(总览!$L$9<>"",B9*100+VALUE(LEFT(C9,LEN(C9)-1))>=总览!$L$9),总览!$M$9,IF(AND(总览!$J$9<>"",B9*100+VALUE(LEFT(C9,LEN(C9)-1))>=总览!$J$9),总览!$K$9,IF(AND(总览!$H$9<>"",B9*100+VALUE(LEFT(C9,LEN(C9)-1))>=总览!$H$9),总览!$I$9,IF(AND(总览!$F$9<>"",B9*100+VALUE(LEFT(C9,LEN(C9)-1))>=总览!$F$9),总览!$G$9,IF(AND(总览!$D$9<>"",B9*100+VALUE(LEFT(C9,LEN(C9)-1))>=总览!$D$9),总览!$E$9,总览!$B$9)))))) | I9: =IF(AND(总览!$L$11<>"",B9*100+VALUE(LEFT(C9,LEN(C9)-1))>=总览!$L$11),总览!$M$11,IF(AND(总览!$J$11<>"",B9*100+VALUE(LEFT(C9,LEN(C9)-1))>=总览!$J$11),总览!$K$11,IF(AND(总览!$H$11<>"",B9*100+VALUE(LEFT(C9,LEN(C9)-1))>=总览!$H$11),总览!$I$11,IF(AND(总览!$F$11<>"",B9*100+VALUE(LEFT(C9,LEN(C9)-1))>=总览!$F$11),总览!$G$11,IF(AND(总览!$D$11<>"",B9*100+VALUE(LEFT(C9,LEN(C9)-1))>=总览!$D$11),总览!$E$11,总览!$B$11))))) | J9: =IF(OR(B9>2027,AND(B9=2027,VALUE(LEFT(C9,LEN(C9)-1))>=9)),IF(AND(总览!$L$12<>"",B9*100+VALUE(LEFT(C9,LEN(C9)-1))>=总览!$L$12),总览!$M$12,IF(AND(总览!$J$12<>"",B9*100+VALUE(LEFT(C9,LEN(C9)-1))>=总览!$J$12),总览!$K$12,IF(AND(总览!$H$12<>"",B9*100+VALUE(LEFT(C9,LEN(C9)-1))>=总览!$H$12),总览!$I$12,IF(AND(总览!$F$12<>"",B9*100+VALUE(LEFT(C9,LEN(C9)-1))>=总览!$F$12),总览!$G$12,IF(AND(总览!$D$12<>"",B9*100+VALUE(LEFT(C9,LEN(C9)-1))>=总览!$D$12),总览!$E$12,总览!$B$12))))),0) | K9: =IF(AND(B9=2026,C9="5月"),120000,IF(AND(B9=2027,C9="9月"),30000,IF(C9="10月",IF(AND(总览!$L$13<>"",B9*100+VALUE(LEFT(C9,LEN(C9)-1))>=总览!$L$13),总览!$M$13,IF(AND(总览!$J$13<>"",B9*100+VALUE(LEFT(C9,LEN(C9)-1))>=总览!$J$13),总览!$K$13,IF(AND(总览!$H$13<>"",B9*100+VALUE(LEFT(C9,LEN(C9)-1))>=总览!$H$13),总览!$I$13,IF(AND(总览!$F$13<>"",B9*100+VALUE(LEFT(C9,LEN(C9)-1))>=总览!$F$13),总览!$G$13,IF(AND(总览!$D$13<>"",B9*100+VALUE(LEFT(C9,LEN(C9)-1))>=总览!$D$13),总览!$E$13,总览!$B$13))))),0))) | M9: =SUM(H9:K9) | N9: =G9-M9 | O9: =O8+N9
A10: 9 | B10: 2026 | C10: 10月 | D10: =IF(AND(总览!$L$6<>"",B10*100+VALUE(LEFT(C10,LEN(C10)-1))>=总览!$L$6),总览!$M$6,IF(AND(总览!$J$6<>"",B10*100+VALUE(LEFT(C10,LEN(C10)-1))>=总览!$J$6),总览!$K$6,IF(AND(总览!$H$6<>"",B10*100+VALUE(LEFT(C10,LEN(C10)-1))>=总览!$H$6),总览!$I$6,IF(AND(总览!$F$6<>"",B10*100+VALUE(LEFT(C10,LEN(C10)-1))>=总览!$F$6),总览!$G$6,IF(AND(总览!$D$6<>"",B10*100+VALUE(LEFT(C10,LEN(C10)-1))>=总览!$D$6),总览!$E$6,总览!$B$6))))) | E10: =IF(C10="12月",IF(AND(总览!$L$7<>"",B10*100+VALUE(LEFT(C10,LEN(C10)-1))>=总览!$L$7),总览!$M$7,IF(AND(总览!$J$7<>"",B10*100+VALUE(LEFT(C10,LEN(C10)-1))>=总览!$J$7),总览!$K$7,IF(AND(总览!$H$7<>"",B10*100+VALUE(LEFT(C10,LEN(C10)-1))>=总览!$H$7),总览!$I$7,IF(AND(总览!$F$7<>"",B10*100+VALUE(LEFT(C10,LEN(C10)-1))>=总览!$F$7),总览!$G$7,IF(AND(总览!$D$7<>"",B10*100+VALUE(LEFT(C10,LEN(C10)-1))>=总览!$D$7),总览!$E$7,总览!$B$7))))),0) | F10: =ROUND(O9*总览!$B$14/12,0) | G10: =D10+E10+F10 | H10: =IF(OR(B10>2027,AND(B10=2027,VALUE(LEFT(C10,LEN(C10)-1))>=9)),IF(AND(总览!$L$10<>"",B10*100+VALUE(LEFT(C10,LEN(C10)-1))>=总览!$L$10),总览!$M$10,IF(AND(总览!$J$10<>"",B10*100+VALUE(LEFT(C10,LEN(C10)-1))>=总览!$J$10),总览!$K$10,IF(AND(总览!$H$10<>"",B10*100+VALUE(LEFT(C10,LEN(C10)-1))>=总览!$H$10),总览!$I$10,IF(AND(总览!$F$10<>"",B10*100+VALUE(LEFT(C10,LEN(C10)-1))>=总览!$F$10),总览!$G$10,IF(AND(总览!$D$10<>"",B10*100+VALUE(LEFT(C10,LEN(C10)-1))>=总览!$D$10),总览!$E$10,总览!$B$10))))),IF(AND(总览!$L$9<>"",B10*100+VALUE(LEFT(C10,LEN(C10)-1))>=总览!$L$9),总览!$M$9,IF(AND(总览!$J$9<>"",B10*100+VALUE(LEFT(C10,LEN(C10)-1))>=总览!$J$9),总览!$K$9,IF(AND(总览!$H$9<>"",B10*100+VALUE(LEFT(C10,LEN(C10)-1))>=总览!$H$9),总览!$I$9,IF(AND(总览!$F$9<>"",B10*100+VALUE(LEFT(C10,LEN(C10)-1))>=总览!$F$9),总览!$G$9,IF(AND(总览!$D$9<>"",B10*100+VALUE(LEFT(C10,LEN(C10)-1))>=总览!$D$9),总览!$E$9,总览!$B$9)))))) | I10: =IF(AND(总览!$L$11<>"",B10*100+VALUE(LEFT(C10,LEN(C10)-1))>=总览!$L$11),总览!$M$11,IF(AND(总览!$J$11<>"",B10*100+VALUE(LEFT(C10,LEN(C10)-1))>=总览!$J$11),总览!$K$11,IF(AND(总览!$H$11<>"",B10*100+VALUE(LEFT(C10,LEN(C10)-1))>=总览!$H$11),总览!$I$11,IF(AND(总览!$F$11<>"",B10*100+VALUE(LEFT(C10,LEN(C10)-1))>=总览!$F$11),总览!$G$11,IF(AND(总览!$D$11<>"",B10*100+VALUE(LEFT(C10,LEN(C10)-1))>=总览!$D$11),总览!$E$11,总览!$B$11))))) | J10: =IF(OR(B10>2027,AND(B10=2027,VALUE(LEFT(C10,LEN(C10)-1))>=9)),IF(AND(总览!$L$12<>"",B10*100+VALUE(LEFT(C10,LEN(C10)-1))>=总览!$L$12),总览!$M$12,IF(AND(总览!$J$12<>"",B10*100+VALUE(LEFT(C10,LEN(C10)-1))>=总览!$J$12),总览!$K$12,IF(AND(总览!$H$12<>"",B10*100+VALUE(LEFT(C10,LEN(C10)-1))>=总览!$H$12),总览!$I$12,IF(AND(总览!$F$12<>"",B10*100+VALUE(LEFT(C10,LEN(C10)-1))>=总览!$F$12),总览!$G$12,IF(AND(总览!$D$12<>"",B10*100+VALUE(LEFT(C10,LEN(C10)-1))>=总览!$D$12),总览!$E$12,总览!$B$12))))),0) | K10: =IF(AND(B10=2026,C10="5月"),120000,IF(AND(B10=2027,C10="9月"),30000,IF(C10="10月",IF(AND(总览!$L$13<>"",B10*100+VALUE(LEFT(C10,LEN(C10)-1))>=总览!$L$13),总览!$M$13,IF(AND(总览!$J$13<>"",B10*100+VALUE(LEFT(C10,LEN(C10)-1))>=总览!$J$13),总览!$K$13,IF(AND(总览!$H$13<>"",B10*100+VALUE(LEFT(C10,LEN(C10)-1))>=总览!$H$13),总览!$I$13,IF(AND(总览!$F$13<>"",B10*100+VALUE(LEFT(C10,LEN(C10)-1))>=总览!$F$13),总览!$G$13,IF(AND(总览!$D$13<>"",B10*100+VALUE(LEFT(C10,LEN(C10)-1))>=总览!$D$13),总览!$E$13,总览!$B$13))))),0))) | L10: 年度旅游 | M10: =SUM(H10:K10) | N10: =G10-M10 | O10: =O9+N10
A11: 10 | B11: 2026 | C11: 11月 | D11: =IF(AND(总览!$L$6<>"",B11*100+VALUE(LEFT(C11,LEN(C11)-1))>=总览!$L$6),总览!$M$6,IF(AND(总览!$J$6<>"",B11*100+VALUE(LEFT(C11,LEN(C11)-1))>=总览!$J$6),总览!$K$6,IF(AND(总览!$H$6<>"",B11*100+VALUE(LEFT(C11,LEN(C11)-1))>=总览!$H$6),总览!$I$6,IF(AND(总览!$F$6<>"",B11*100+VALUE(LEFT(C11,LEN(C11)-1))>=总览!$F$6),总览!$G$6,IF(AND(总览!$D$6<>"",B11*100+VALUE(LEFT(C11,LEN(C11)-1))>=总览!$D$6),总览!$E$6,总览!$B$6))))) | E11: =IF(C11="12月",IF(AND(总览!$L$7<>"",B11*100+VALUE(LEFT(C11,LEN(C11)-1))>=总览!$L$7),总览!$M$7,IF(AND(总览!$J$7<>"",B11*100+VALUE(LEFT(C11,LEN(C11)-1))>=总览!$J$7),总览!$K$7,IF(AND(总览!$H$7<>"",B11*100+VALUE(LEFT(C11,LEN(C11)-1))>=总览!$H$7),总览!$I$7,IF(AND(总览!$F$7<>"",B11*100+VALUE(LEFT(C11,LEN(C11)-1))>=总览!$F$7),总览!$G$7,IF(AND(总览!$D$7<>"",B11*100+VALUE(LEFT(C11,LEN(C11)-1))>=总览!$D$7),总览!$E$7,总览!$B$7))))),0) | F11: =ROUND(O10*总览!$B$14/12,0) | G11: =D11+E11+F11 | H11: =IF(OR(B11>2027,AND(B11=2027,VALUE(LEFT(C11,LEN(C11)-1))>=9)),IF(AND(总览!$L$10<>"",B11*100+VALUE(LEFT(C11,LEN(C11)-1))>=总览!$L$10),总览!$M$10,IF(AND(总览!$J$10<>"",B11*100+VALUE(LEFT(C11,LEN(C11)-1))>=总览!$J$10),总览!$K$10,IF(AND(总览!$H$10<>"",B11*100+VALUE(LEFT(C11,LEN(C11)-1))>=总览!$H$10),总览!$I$10,IF(AND(总览!$F$10<>"",B11*100+VALUE(LEFT(C11,LEN(C11)-1))>=总览!$F$10),总览!$G$10,IF(AND(总览!$D$10<>"",B11*100+VALUE(LEFT(C11,LEN(C11)-1))>=总览!$D$10),总览!$E$10,总览!$B$10))))),IF(AND(总览!$L$9<>"",B11*100+VALUE(LEFT(C11,LEN(C11)-1))>=总览!$L$9),总览!$M$9,IF(AND(总览!$J$9<>"",B11*100+VALUE(LEFT(C11,LEN(C11)-1))>=总览!$J$9),总览!$K$9,IF(AND(总览!$H$9<>"",B11*100+VALUE(LEFT(C11,LEN(C11)-1))>=总览!$H$9),总览!$I$9,IF(AND(总览!$F$9<>"",B11*100+VALUE(LEFT(C11,LEN(C11)-1))>=总览!$F$9),总览!$G$9,IF(AND(总览!$D$9<>"",B11*100+VALUE(LEFT(C11,LEN(C11)-1))>=总览!$D$9),总览!$E$9,总览!$B$9)))))) | I11: =IF(AND(总览!$L$11<>"",B11*100+VALUE(LEFT(C11,LEN(C11)-1))>=总览!$L$11),总览!$M$11,IF(AND(总览!$J$11<>"",B11*100+VALUE(LEFT(C11,LEN(C11)-1))>=总览!$J$11),总览!$K$11,IF(AND(总览!$H$11<>"",B11*100+VALUE(LEFT(C11,LEN(C11)-1))>=总览!$H$11),总览!$I$11,IF(AND(总览!$F$11<>"",B11*100+VALUE(LEFT(C11,LEN(C11)-1))>=总览!$F$11),总览!$G$11,IF(AND(总览!$D$11<>"",B11*100+VALUE(LEFT(C11,LEN(C11)-1))>=总览!$D$11),总览!$E$11,总览!$B$11))))) | J11: =IF(OR(B11>2027,AND(B11=2027,VALUE(LEFT(C11,LEN(C11)-1))>=9)),IF(AND(总览!$L$12<>"",B11*100+VALUE(LEFT(C11,LEN(C11)-1))>=总览!$L$12),总览!$M$12,IF(AND(总览!$J$12<>"",B11*100+VALUE(LEFT(C11,LEN(C11)-1))>=总览!$J$12),总览!$K$12,IF(AND(总览!$H$12<>"",B11*100+VALUE(LEFT(C11,LEN(C11)-1))>=总览!$H$12),总览!$I$12,IF(AND(总览!$F$12<>"",B11*100+VALUE(LEFT(C11,LEN(C11)-1))>=总览!$F$12),总览!$G$12,IF(AND(总览!$D$12<>"",B11*100+VALUE(LEFT(C11,LEN(C11)-1))>=总览!$D$12),总览!$E$12,总览!$B$12))))),0) | K11: =IF(AND(B11=2026,C11="5月"),120000,IF(AND(B11=2027,C11="9月"),30000,IF(C11="10月",IF(AND(总览!$L$13<>"",B11*100+VALUE(LEFT(C11,LEN(C11)-1))>=总览!$L$13),总览!$M$13,IF(AND(总览!$J$13<>"",B11*100+VALUE(LEFT(C11,LEN(C11)-1))>=总览!$J$13),总览!$K$13,IF(AND(总览!$H$13<>"",B11*100+VALUE(LEFT(C11,LEN(C11)-1))>=总览!$H$13),总览!$I$13,IF(AND(总览!$F$13<>"",B11*100+VALUE(LEFT(C11,LEN(C11)-1))>=总览!$F$13),总览!$G$13,IF(AND(总览!$D$13<>"",B11*100+VALUE(LEFT(C11,LEN(C11)-1))>=总览!$D$13),总览!$E$13,总览!$B$13))))),0))) | M11: =SUM(H11:K11) | N11: =G11-M11 | O11: =O10+N11
A12: 11 | B12: 2026 | C12: 12月 | D12: =IF(AND(总览!$L$6<>"",B12*100+VALUE(LEFT(C12,LEN(C12)-1))>=总览!$L$6),总览!$M$6,IF(AND(总览!$J$6<>"",B12*100+VALUE(LEFT(C12,LEN(C12)-1))>=总览!$J$6),总览!$K$6,IF(AND(总览!$H$6<>"",B12*100+VALUE(LEFT(C12,LEN(C12)-1))>=总览!$H$6),总览!$I$6,IF(AND(总览!$F$6<>"",B12*100+VALUE(LEFT(C12,LEN(C12)-1))>=总览!$F$6),总览!$G$6,IF(AND(总览!$D$6<>"",B12*100+VALUE(LEFT(C12,LEN(C12)-1))>=总览!$D$6),总览!$E$6,总览!$B$6))))) | E12: =IF(C12="12月",IF(AND(总览!$L$7<>"",B12*100+VALUE(LEFT(C12,LEN(C12)-1))>=总览!$L$7),总览!$M$7,IF(AND(总览!$J$7<>"",B12*100+VALUE(LEFT(C12,LEN(C12)-1))>=总览!$J$7),总览!$K$7,IF(AND(总览!$H$7<>"",B12*100+VALUE(LEFT(C12,LEN(C12)-1))>=总览!$H$7),总览!$I$7,IF(AND(总览!$F$7<>"",B12*100+VALUE(LEFT(C12,LEN(C12)-1))>=总览!$F$7),总览!$G$7,IF(AND(总览!$D$7<>"",B12*100+VALUE(LEFT(C12,LEN(C12)-1))>=总览!$D$7),总览!$E$7,总览!$B$7))))),0) | F12: =ROUND(O11*总览!$B$14/12,0) | G12: =D12+E12+F12 | H12: =IF(OR(B12>2027,AND(B12=2027,VALUE(LEFT(C12,LEN(C12)-1))>=9)),IF(AND(总览!$L$10<>"",B12*100+VALUE(LEFT(C12,LEN(C12)-1))>=总览!$L$10),总览!$M$10,IF(AND(总览!$J$10<>"",B12*100+VALUE(LEFT(C12,LEN(C12)-1))>=总览!$J$10),总览!$K$10,IF(AND(总览!$H$10<>"",B12*100+VALUE(LEFT(C12,LEN(C12)-1))>=总览!$H$10),总览!$I$10,IF(AND(总览!$F$10<>"",B12*100+VALUE(LEFT(C12,LEN(C12)-1))>=总览!$F$10),总览!$G$10,IF(AND(总览!$D$10<>"",B12*100+VALUE(LEFT(C12,LEN(C12)-1))>=总览!$D$10),总览!$E$10,总览!$B$10))))),IF(AND(总览!$L$9<>"",B12*100+VALUE(LEFT(C12,LEN(C12)-1))>=总览!$L$9),总览!$M$9,IF(AND(总览!$J$9<>"",B12*100+VALUE(LEFT(C12,LEN(C12)-1))>=总览!$J$9),总览!$K$9,IF(AND(总览!$H$9<>"",B12*100+VALUE(LEFT(C12,LEN(C12)-1))>=总览!$H$9),总览!$I$9,IF(AND(总览!$F$9<>"",B12*100+VALUE(LEFT(C12,LEN(C12)-1))>=总览!$F$9),总览!$G$9,IF(AND(总览!$D$9<>"",B12*100+VALUE(LEFT(C12,LEN(C12)-1))>=总览!$D$9),总览!$E$9,总览!$B$9)))))) | I12: =IF(AND(总览!$L$11<>"",B12*100+VALUE(LEFT(C12,LEN(C12)-1))>=总览!$L$11),总览!$M$11,IF(AND(总览!$J$11<>"",B12*100+VALUE(LEFT(C12,LEN(C12)-1))>=总览!$J$11),总览!$K$11,IF(AND(总览!$H$11<>"",B12*100+VALUE(LEFT(C12,LEN(C12)-1))>=总览!$H$11),总览!$I$11,IF(AND(总览!$F$11<>"",B12*100+VALUE(LEFT(C12,LEN(C12)-1))>=总览!$F$11),总览!$G$11,IF(AND(总览!$D$11<>"",B12*100+VALUE(LEFT(C12,LEN(C12)-1))>=总览!$D$11),总览!$E$11,总览!$B$11))))) | J12: =IF(OR(B12>2027,AND(B12=2027,VALUE(LEFT(C12,LEN(C12)-1))>=9)),IF(AND(总览!$L$12<>"",B12*100+VALUE(LEFT(C12,LEN(C12)-1))>=总览!$L$12),总览!$M$12,IF(AND(总览!$J$12<>"",B12*100+VALUE(LEFT(C12,LEN(C12)-1))>=总览!$J$12),总览!$K$12,IF(AND(总览!$H$12<>"",B12*100+VALUE(LEFT(C12,LEN(C12)-1))>=总览!$H$12),总览!$I$12,IF(AND(总览!$F$12<>"",B12*100+VALUE(LEFT(C12,LEN(C12)-1))>=总览!$F$12),总览!$G$12,IF(AND(总览!$D$12<>"",B12*100+VALUE(LEFT(C12,LEN(C12)-1))>=总览!$D$12),总览!$E$12,总览!$B$12))))),0) | K12: =IF(AND(B12=2026,C12="5月"),120000,IF(AND(B12=2027,C12="9月"),30000,IF(C12="10月",IF(AND(总览!$L$13<>"",B12*100+VALUE(LEFT(C12,LEN(C12)-1))>=总览!$L$13),总览!$M$13,IF(AND(总览!$J$13<>"",B12*100+VALUE(LEFT(C12,LEN(C12)-1))>=总览!$J$13),总览!$K$13,IF(AND(总览!$H$13<>"",B12*100+VALUE(LEFT(C12,LEN(C12)-1))>=总览!$H$13),总览!$I$13,IF(AND(总览!$F$13<>"",B12*100+VALUE(LEFT(C12,LEN(C12)-1))>=总览!$F$13),总览!$G$13,IF(AND(总览!$D$13<>"",B12*100+VALUE(LEFT(C12,LEN(C12)-1))>=总览!$D$13),总览!$E$13,总览!$B$13))))),0))) | M12: =SUM(H12:K12) | N12: =G12-M12 | O12: =O11+N12
A13: 12 | B13: 2027 | C13: 1月 | D13: =IF(AND(总览!$L$6<>"",B13*100+VALUE(LEFT(C13,LEN(C13)-1))>=总览!$L$6),总览!$M$6,IF(AND(总览!$J$6<>"",B13*100+VALUE(LEFT(C13,LEN(C13)-1))>=总览!$J$6),总览!$K$6,IF(AND(总览!$H$6<>"",B13*100+VALUE(LEFT(C13,LEN(C13)-1))>=总览!$H$6),总览!$I$6,IF(AND(总览!$F$6<>"",B13*100+VALUE(LEFT(C13,LEN(C13)-1))>=总览!$F$6),总览!$G$6,IF(AND(总览!$D$6<>"",B13*100+VALUE(LEFT(C13,LEN(C13)-1))>=总览!$D$6),总览!$E$6,总览!$B$6))))) | E13: =IF(C13="12月",IF(AND(总览!$L$7<>"",B13*100+VALUE(LEFT(C13,LEN(C13)-1))>=总览!$L$7),总览!$M$7,IF(AND(总览!$J$7<>"",B13*100+VALUE(LEFT(C13,LEN(C13)-1))>=总览!$J$7),总览!$K$7,IF(AND(总览!$H$7<>"",B13*100+VALUE(LEFT(C13,LEN(C13)-1))>=总览!$H$7),总览!$I$7,IF(AND(总览!$F$7<>"",B13*100+VALUE(LEFT(C13,LEN(C13)-1))>=总览!$F$7),总览!$G$7,IF(AND(总览!$D$7<>"",B13*100+VALUE(LEFT(C13,LEN(C13)-1))>=总览!$D$7),总览!$E$7,总览!$B$7))))),0) | F13: =ROUND(O12*总览!$B$14/12,0) | G13: =D13+E13+F13 | H13: =IF(OR(B13>2027,AND(B13=2027,VALUE(LEFT(C13,LEN(C13)-1))>=9)),IF(AND(总览!$L$10<>"",B13*100+VALUE(LEFT(C13,LEN(C13)-1))>=总览!$L$10),总览!$M$10,IF(AND(总览!$J$10<>"",B13*100+VALUE(LEFT(C13,LEN(C13)-1))>=总览!$J$10),总览!$K$10,IF(AND(总览!$H$10<>"",B13*100+VALUE(LEFT(C13,LEN(C13)-1))>=总览!$H$10),总览!$I$10,IF(AND(总览!$F$10<>"",B13*100+VALUE(LEFT(C13,LEN(C13)-1))>=总览!$F$10),总览!$G$10,IF(AND(总览!$D$10<>"",B13*100+VALUE(LEFT(C13,LEN(C13)-1))>=总览!$D$10),总览!$E$10,总览!$B$10))))),IF(AND(总览!$L$9<>"",B13*100+VALUE(LEFT(C13,LEN(C13)-1))>=总览!$L$9),总览!$M$9,IF(AND(总览!$J$9<>"",B13*100+VALUE(LEFT(C13,LEN(C13)-1))>=总览!$J$9),总览!$K$9,IF(AND(总览!$H$9<>"",B13*100+VALUE(LEFT(C13,LEN(C13)-1))>=总览!$H$9),总览!$I$9,IF(AND(总览!$F$9<>"",B13*100+VALUE(LEFT(C13,LEN(C13)-1))>=总览!$F$9),总览!$G$9,IF(AND(总览!$D$9<>"",B13*100+VALUE(LEFT(C13,LEN(C13)-1))>=总览!$D$9),总览!$E$9,总览!$B$9)))))) | I13: =IF(AND(总览!$L$11<>"",B13*100+VALUE(LEFT(C13,LEN(C13)-1))>=总览!$L$11),总览!$M$11,IF(AND(总览!$J$11<>"",B13*100+VALUE(LEFT(C13,LEN(C13)-1))>=总览!$J$11),总览!$K$11,IF(AND(总览!$H$11<>"",B13*100+VALUE(LEFT(C13,LEN(C13)-1))>=总览!$H$11),总览!$I$11,IF(AND(总览!$F$11<>"",B13*100+VALUE(LEFT(C13,LEN(C13)-1))>=总览!$F$11),总览!$G$11,IF(AND(总览!$D$11<>"",B13*100+VALUE(LEFT(C13,LEN(C13)-1))>=总览!$D$11),总览!$E$11,总览!$B$11))))) | J13: =IF(OR(B13>2027,AND(B13=2027,VALUE(LEFT(C13,LEN(C13)-1))>=9)),IF(AND(总览!$L$12<>"",B13*100+VALUE(LEFT(C13,LEN(C13)-1))>=总览!$L$12),总览!$M$12,IF(AND(总览!$J$12<>"",B13*100+VALUE(LEFT(C13,LEN(C13)-1))>=总览!$J$12),总览!$K$12,IF(AND(总览!$H$12<>"",B13*100+VALUE(LEFT(C13,LEN(C13)-1))>=总览!$H$12),总览!$I$12,IF(AND(总览!$F$12<>"",B13*100+VALUE(LEFT(C13,LEN(C13)-1))>=总览!$F$12),总览!$G$12,IF(AND(总览!$D$12<>"",B13*100+VALUE(LEFT(C13,LEN(C13)-1))>=总览!$D$12),总览!$E$12,总览!$B$12))))),0) | K13: =IF(AND(B13=2026,C13="5月"),120000,IF(AND(B13=2027,C13="9月"),30000,IF(C13="10月",IF(AND(总览!$L$13<>"",B13*100+VALUE(LEFT(C13,LEN(C13)-1))>=总览!$L$13),总览!$M$13,IF(AND(总览!$J$13<>"",B13*100+VALUE(LEFT(C13,LEN(C13)-1))>=总览!$J$13),总览!$K$13,IF(AND(总览!$H$13<>"",B13*100+VALUE(LEFT(C13,LEN(C13)-1))>=总览!$H$13),总览!$I$13,IF(AND(总览!$F$13<>"",B13*100+VALUE(LEFT(C13,LEN(C13)-1))>=总览!$F$13),总览!$G$13,IF(AND(总览!$D$13<>"",B13*100+VALUE(LEFT(C13,LEN(C13)-1))>=总览!$D$13),总览!$E$13,总览!$B$13))))),0))) | M13: =SUM(H13:K13) | N13: =G13-M13 | O13: =O12+N13
A14: 13 | B14: 2027 | C14: 2月 | D14: =IF(AND(总览!$L$6<>"",B14*100+VALUE(LEFT(C14,LEN(C14)-1))>=总览!$L$6),总览!$M$6,IF(AND(总览!$J$6<>"",B14*100+VALUE(LEFT(C14,LEN(C14)-1))>=总览!$J$6),总览!$K$6,IF(AND(总览!$H$6<>"",B14*100+VALUE(LEFT(C14,LEN(C14)-1))>=总览!$H$6),总览!$I$6,IF(AND(总览!$F$6<>"",B14*100+VALUE(LEFT(C14,LEN(C14)-1))>=总览!$F$6),总览!$G$6,IF(AND(总览!$D$6<>"",B14*100+VALUE(LEFT(C14,LEN(C14)-1))>=总览!$D$6),总览!$E$6,总览!$B$6))))) | E14: =IF(C14="12月",IF(AND(总览!$L$7<>"",B14*100+VALUE(LEFT(C14,LEN(C14)-1))>=总览!$L$7),总览!$M$7,IF(AND(总览!$J$7<>"",B14*100+VALUE(LEFT(C14,LEN(C14)-1))>=总览!$J$7),总览!$K$7,IF(AND(总览!$H$7<>"",B14*100+VALUE(LEFT(C14,LEN(C14)-1))>=总览!$H$7),总览!$I$7,IF(AND(总览!$F$7<>"",B14*100+VALUE(LEFT(C14,LEN(C14)-1))>=总览!$F$7),总览!$G$7,IF(AND(总览!$D$7<>"",B14*100+VALUE(LEFT(C14,LEN(C14)-1))>=总览!$D$7),总览!$E$7,总览!$B$7))))),0) | F14: =ROUND(O13*总览!$B$14/12,0) | G14: =D14+E14+F14 | H14: =IF(OR(B14>2027,AND(B14=2027,VALUE(LEFT(C14,LEN(C14)-1))>=9)),IF(AND(总览!$L$10<>"",B14*100+VALUE(LEFT(C14,LEN(C14)-1))>=总览!$L$10),总览!$M$10,IF(AND(总览!$J$10<>"",B14*100+VALUE(LEFT(C14,LEN(C14)-1))>=总览!$J$10),总览!$K$10,IF(AND(总览!$H$10<>"",B14*100+VALUE(LEFT(C14,LEN(C14)-1))>=总览!$H$10),总览!$I$10,IF(AND(总览!$F$10<>"",B14*100+VALUE(LEFT(C14,LEN(C14)-1))>=总览!$F$10),总览!$G$10,IF(AND(总览!$D$10<>"",B14*100+VALUE(LEFT(C14,LEN(C14)-1))>=总览!$D$10),总览!$E$10,总览!$B$10))))),IF(AND(总览!$L$9<>"",B14*100+VALUE(LEFT(C14,LEN(C14)-1))>=总览!$L$9),总览!$M$9,IF(AND(总览!$J$9<>"",B14*100+VALUE(LEFT(C14,LEN(C14)-1))>=总览!$J$9),总览!$K$9,IF(AND(总览!$H$9<>"",B14*100+VALUE(LEFT(C14,LEN(C14)-1))>=总览!$H$9),总览!$I$9,IF(AND(总览!$F$9<>"",B14*100+VALUE(LEFT(C14,LEN(C14)-1))>=总览!$F$9),总览!$G$9,IF(AND(总览!$D$9<>"",B14*100+VALUE(LEFT(C14,LEN(C14)-1))>=总览!$D$9),总览!$E$9,总览!$B$9)))))) | I14: =IF(AND(总览!$L$11<>"",B14*100+VALUE(LEFT(C14,LEN(C14)-1))>=总览!$L$11),总览!$M$11,IF(AND(总览!$J$11<>"",B14*100+VALUE(LEFT(C14,LEN(C14)-1))>=总览!$J$11),总览!$K$11,IF(AND(总览!$H$11<>"",B14*100+VALUE(LEFT(C14,LEN(C14)-1))>=总览!$H$11),总览!$I$11,IF(AND(总览!$F$11<>"",B14*100+VALUE(LEFT(C14,LEN(C14)-1))>=总览!$F$11),总览!$G$11,IF(AND(总览!$D$11<>"",B14*100+VALUE(LEFT(C14,LEN(C14)-1))>=总览!$D$11),总览!$E$11,总览!$B$11))))) | J14: =IF(OR(B14>2027,AND(B14=2027,VALUE(LEFT(C14,LEN(C14)-1))>=9)),IF(AND(总览!$L$12<>"",B14*100+VALUE(LEFT(C14,LEN(C14)-1))>=总览!$L$12),总览!$M$12,IF(AND(总览!$J$12<>"",B14*100+VALUE(LEFT(C14,LEN(C14)-1))>=总览!$J$12),总览!$K$12,IF(AND(总览!$H$12<>"",B14*100+VALUE(LEFT(C14,LEN(C14)-1))>=总览!$H$12),总览!$I$12,IF(AND(总览!$F$12<>"",B14*100+VALUE(LEFT(C14,LEN(C14)-1))>=总览!$F$12),总览!$G$12,IF(AND(总览!$D$12<>"",B14*100+VALUE(LEFT(C14,LEN(C14)-1))>=总览!$D$12),总览!$E$12,总览!$B$12))))),0) | K14: =IF(AND(B14=2026,C14="5月"),120000,IF(AND(B14=2027,C14="9月"),30000,IF(C14="10月",IF(AND(总览!$L$13<>"",B14*100+VALUE(LEFT(C14,LEN(C14)-1))>=总览!$L$13),总览!$M$13,IF(AND(总览!$J$13<>"",B14*100+VALUE(LEFT(C14,LEN(C14)-1))>=总览!$J$13),总览!$K$13,IF(AND(总览!$H$13<>"",B14*100+VALUE(LEFT(C14,LEN(C14)-1))>=总览!$H$13),总览!$I$13,IF(AND(总览!$F$13<>"",B14*100+VALUE(LEFT(C14,LEN(C14)-1))>=总览!$F$13),总览!$G$13,IF(AND(总览!$D$13<>"",B14*100+VALUE(LEFT(C14,LEN(C14)-1))>=总览!$D$13),总览!$E$13,总览!$B$13))))),0))) | M14: =SUM(H14:K14) | N14: =G14-M14 | O14: =O13+N14
A15: 14 | B15: 2027 | C15: 3月 | D15: =IF(AND(总览!$L$6<>"",B15*100+VALUE(LEFT(C15,LEN(C15)-1))>=总览!$L$6),总览!$M$6,IF(AND(总览!$J$6<>"",B15*100+VALUE(LEFT(C15,LEN(C15)-1))>=总览!$J$6),总览!$K$6,IF(AND(总览!$H$6<>"",B15*100+VALUE(LEFT(C15,LEN(C15)-1))>=总览!$H$6),总览!$I$6,IF(AND(总览!$F$6<>"",B15*100+VALUE(LEFT(C15,LEN(C15)-1))>=总览!$F$6),总览!$G$6,IF(AND(总览!$D$6<>"",B15*100+VALUE(LEFT(C15,LEN(C15)-1))>=总览!$D$6),总览!$E$6,总览!$B$6))))) | E15: =IF(C15="12月",IF(AND(总览!$L$7<>"",B15*100+VALUE(LEFT(C15,LEN(C15)-1))>=总览!$L$7),总览!$M$7,IF(AND(总览!$J$7<>"",B15*100+VALUE(LEFT(C15,LEN(C15)-1))>=总览!$J$7),总览!$K$7,IF(AND(总览!$H$7<>"",B15*100+VALUE(LEFT(C15,LEN(C15)-1))>=总览!$H$7),总览!$I$7,IF(AND(总览!$F$7<>"",B15*100+VALUE(LEFT(C15,LEN(C15)-1))>=总览!$F$7),总览!$G$7,IF(AND(总览!$D$7<>"",B15*100+VALUE(LEFT(C15,LEN(C15)-1))>=总览!$D$7),总览!$E$7,总览!$B$7))))),0) | F15: =ROUND(O14*总览!$B$14/12,0) | G15: =D15+E15+F15 | H15: =IF(OR(B15>2027,AND(B15=2027,VALUE(LEFT(C15,LEN(C15)-1))>=9)),IF(AND(总览!$L$10<>"",B15*100+VALUE(LEFT(C15,LEN(C15)-1))>=总览!$L$10),总览!$M$10,IF(AND(总览!$J$10<>"",B15*100+VALUE(LEFT(C15,LEN(C15)-1))>=总览!$J$10),总览!$K$10,IF(AND(总览!$H$10<>"",B15*100+VALUE(LEFT(C15,LEN(C15)-1))>=总览!$H$10),总览!$I$10,IF(AND(总览!$F$10<>"",B15*100+VALUE(LEFT(C15,LEN(C15)-1))>=总览!$F$10),总览!$G$10,IF(AND(总览!$D$10<>"",B15*100+VALUE(LEFT(C15,LEN(C15)-1))>=总览!$D$10),总览!$E$10,总览!$B$10))))),IF(AND(总览!$L$9<>"",B15*100+VALUE(LEFT(C15,LEN(C15)-1))>=总览!$L$9),总览!$M$9,IF(AND(总览!$J$9<>"",B15*100+VALUE(LEFT(C15,LEN(C15)-1))>=总览!$J$9),总览!$K$9,IF(AND(总览!$H$9<>"",B15*100+VALUE(LEFT(C15,LEN(C15)-1))>=总览!$H$9),总览!$I$9,IF(AND(总览!$F$9<>"",B15*100+VALUE(LEFT(C15,LEN(C15)-1))>=总览!$F$9),总览!$G$9,IF(AND(总览!$D$9<>"",B15*100+VALUE(LEFT(C15,LEN(C15)-1))>=总览!$D$9),总览!$E$9,总览!$B$9)))))) | I15: =IF(AND(总览!$L$11<>"",B15*100+VALUE(LEFT(C15,LEN(C15)-1))>=总览!$L$11),总览!$M$11,IF(AND(总览!$J$11<>"",B15*100+VALUE(LEFT(C15,LEN(C15)-1))>=总览!$J$11),总览!$K$11,IF(AND(总览!$H$11<>"",B15*100+VALUE(LEFT(C15,LEN(C15)-1))>=总览!$H$11),总览!$I$11,IF(AND(总览!$F$11<>"",B15*100+VALUE(LEFT(C15,LEN(C15)-1))>=总览!$F$11),总览!$G$11,IF(AND(总览!$D$11<>"",B15*100+VALUE(LEFT(C15,LEN(C15)-1))>=总览!$D$11),总览!$E$11,总览!$B$11))))) | J15: =IF(OR(B15>2027,AND(B15=2027,VALUE(LEFT(C15,LEN(C15)-1))>=9)),IF(AND(总览!$L$12<>"",B15*100+VALUE(LEFT(C15,LEN(C15)-1))>=总览!$L$12),总览!$M$12,IF(AND(总览!$J$12<>"",B15*100+VALUE(LEFT(C15,LEN(C15)-1))>=总览!$J$12),总览!$K$12,IF(AND(总览!$H$12<>"",B15*100+VALUE(LEFT(C15,LEN(C15)-1))>=总览!$H$12),总览!$I$12,IF(AND(总览!$F$12<>"",B15*100+VALUE(LEFT(C15,LEN(C15)-1))>=总览!$F$12),总览!$G$12,IF(AND(总览!$D$12<>"",B15*100+VALUE(LEFT(C15,LEN(C15)-1))>=总览!$D$12),总览!$E$12,总览!$B$12))))),0) | K15: =IF(AND(B15=2026,C15="5月"),120000,IF(AND(B15=2027,C15="9月"),30000,IF(C15="10月",IF(AND(总览!$L$13<>"",B15*100+VALUE(LEFT(C15,LEN(C15)-1))>=总览!$L$13),总览!$M$13,IF(AND(总览!$J$13<>"",B15*100+VALUE(LEFT(C15,LEN(C15)-1))>=总览!$J$13),总览!$K$13,IF(AND(总览!$H$13<>"",B15*100+VALUE(LEFT(C15,LEN(C15)-1))>=总览!$H$13),总览!$I$13,IF(AND(总览!$F$13<>"",B15*100+VALUE(LEFT(C15,LEN(C15)-1))>=总览!$F$13),总览!$G$13,IF(AND(总览!$D$13<>"",B15*100+VALUE(LEFT(C15,LEN(C15)-1))>=总览!$D$13),总览!$E$13,总览!$B$13))))),0))) | M15: =SUM(H15:K15) | N15: =G15-M15 | O15: =O14+N15
A16: 15 | B16: 2027 | C16: 4月 | D16: =IF(AND(总览!$L$6<>"",B16*100+VALUE(LEFT(C16,LEN(C16)-1))>=总览!$L$6),总览!$M$6,IF(AND(总览!$J$6<>"",B16*100+VALUE(LEFT(C16,LEN(C16)-1))>=总览!$J$6),总览!$K$6,IF(AND(总览!$H$6<>"",B16*100+VALUE(LEFT(C16,LEN(C16)-1))>=总览!$H$6),总览!$I$6,IF(AND(总览!$F$6<>"",B16*100+VALUE(LEFT(C16,LEN(C16)-1))>=总览!$F$6),总览!$G$6,IF(AND(总览!$D$6<>"",B16*100+VALUE(LEFT(C16,LEN(C16)-1))>=总览!$D$6),总览!$E$6,总览!$B$6))))) | E16: =IF(C16="12月",IF(AND(总览!$L$7<>"",B16*100+VALUE(LEFT(C16,LEN(C16)-1))>=总览!$L$7),总览!$M$7,IF(AND(总览!$J$7<>"",B16*100+VALUE(LEFT(C16,LEN(C16)-1))>=总览!$J$7),总览!$K$7,IF(AND(总览!$H$7<>"",B16*100+VALUE(LEFT(C16,LEN(C16)-1))>=总览!$H$7),总览!$I$7,IF(AND(总览!$F$7<>"",B16*100+VALUE(LEFT(C16,LEN(C16)-1))>=总览!$F$7),总览!$G$7,IF(AND(总览!$D$7<>"",B16*100+VALUE(LEFT(C16,LEN(C16)-1))>=总览!$D$7),总览!$E$7,总览!$B$7))))),0) | F16: =ROUND(O15*总览!$B$14/12,0) | G16: =D16+E16+F16 | H16: =IF(OR(B16>2027,AND(B16=2027,VALUE(LEFT(C16,LEN(C16)-1))>=9)),IF(AND(总览!$L$10<>"",B16*100+VALUE(LEFT(C16,LEN(C16)-1))>=总览!$L$10),总览!$M$10,IF(AND(总览!$J$10<>"",B16*100+VALUE(LEFT(C16,LEN(C16)-1))>=总览!$J$10),总览!$K$10,IF(AND(总览!$H$10<>"",B16*100+VALUE(LEFT(C16,LEN(C16)-1))>=总览!$H$10),总览!$I$10,IF(AND(总览!$F$10<>"",B16*100+VALUE(LEFT(C16,LEN(C16)-1))>=总览!$F$10),总览!$G$10,IF(AND(总览!$D$10<>"",B16*100+VALUE(LEFT(C16,LEN(C16)-1))>=总览!$D$10),总览!$E$10,总览!$B$10))))),IF(AND(总览!$L$9<>"",B16*100+VALUE(LEFT(C16,LEN(C16)-1))>=总览!$L$9),总览!$M$9,IF(AND(总览!$J$9<>"",B16*100+VALUE(LEFT(C16,LEN(C16)-1))>=总览!$J$9),总览!$K$9,IF(AND(总览!$H$9<>"",B16*100+VALUE(LEFT(C16,LEN(C16)-1))>=总览!$H$9),总览!$I$9,IF(AND(总览!$F$9<>"",B16*100+VALUE(LEFT(C16,LEN(C16)-1))>=总览!$F$9),总览!$G$9,IF(AND(总览!$D$9<>"",B16*100+VALUE(LEFT(C16,LEN(C16)-1))>=总览!$D$9),总览!$E$9,总览!$B$9)))))) | I16: =IF(AND(总览!$L$11<>"",B16*100+VALUE(LEFT(C16,LEN(C16)-1))>=总览!$L$11),总览!$M$11,IF(AND(总览!$J$11<>"",B16*100+VALUE(LEFT(C16,LEN(C16)-1))>=总览!$J$11),总览!$K$11,IF(AND(总览!$H$11<>"",B16*100+VALUE(LEFT(C16,LEN(C16)-1))>=总览!$H$11),总览!$I$11,IF(AND(总览!$F$11<>"",B16*100+VALUE(LEFT(C16,LEN(C16)-1))>=总览!$F$11),总览!$G$11,IF(AND(总览!$D$11<>"",B16*100+VALUE(LEFT(C16,LEN(C16)-1))>=总览!$D$11),总览!$E$11,总览!$B$11))))) | J16: =IF(OR(B16>2027,AND(B16=2027,VALUE(LEFT(C16,LEN(C16)-1))>=9)),IF(AND(总览!$L$12<>"",B16*100+VALUE(LEFT(C16,LEN(C16)-1))>=总览!$L$12),总览!$M$12,IF(AND(总览!$J$12<>"",B16*100+VALUE(LEFT(C16,LEN(C16)-1))>=总览!$J$12),总览!$K$12,IF(AND(总览!$H$12<>"",B16*100+VALUE(LEFT(C16,LEN(C16)-1))>=总览!$H$12),总览!$I$12,IF(AND(总览!$F$12<>"",B16*100+VALUE(LEFT(C16,LEN(C16)-1))>=总览!$F$12),总览!$G$12,IF(AND(总览!$D$12<>"",B16*100+VALUE(LEFT(C16,LEN(C16)-1))>=总览!$D$12),总览!$E$12,总览!$B$12))))),0) | K16: =IF(AND(B16=2026,C16="5月"),120000,IF(AND(B16=2027,C16="9月"),30000,IF(C16="10月",IF(AND(总览!$L$13<>"",B16*100+VALUE(LEFT(C16,LEN(C16)-1))>=总览!$L$13),总览!$M$13,IF(AND(总览!$J$13<>"",B16*100+VALUE(LEFT(C16,LEN(C16)-1))>=总览!$J$13),总览!$K$13,IF(AND(总览!$H$13<>"",B16*100+VALUE(LEFT(C16,LEN(C16)-1))>=总览!$H$13),总览!$I$13,IF(AND(总览!$F$13<>"",B16*100+VALUE(LEFT(C16,LEN(C16)-1))>=总览!$F$13),总览!$G$13,IF(AND(总览!$D$13<>"",B16*100+VALUE(LEFT(C16,LEN(C16)-1))>=总览!$D$13),总览!$E$13,总览!$B$13))))),0))) | M16: =SUM(H16:K16) | N16: =G16-M16 | O16: =O15+N16
A17: 16 | B17: 2027 | C17: 5月 | D17: =IF(AND(总览!$L$6<>"",B17*100+VALUE(LEFT(C17,LEN(C17)-1))>=总览!$L$6),总览!$M$6,IF(AND(总览!$J$6<>"",B17*100+VALUE(LEFT(C17,LEN(C17)-1))>=总览!$J$6),总览!$K$6,IF(AND(总览!$H$6<>"",B17*100+VALUE(LEFT(C17,LEN(C17)-1))>=总览!$H$6),总览!$I$6,IF(AND(总览!$F$6<>"",B17*100+VALUE(LEFT(C17,LEN(C17)-1))>=总览!$F$6),总览!$G$6,IF(AND(总览!$D$6<>"",B17*100+VALUE(LEFT(C17,LEN(C17)-1))>=总览!$D$6),总览!$E$6,总览!$B$6))))) | E17: =IF(C17="12月",IF(AND(总览!$L$7<>"",B17*100+VALUE(LEFT(C17,LEN(C17)-1))>=总览!$L$7),总览!$M$7,IF(AND(总览!$J$7<>"",B17*100+VALUE(LEFT(C17,LEN(C17)-1))>=总览!$J$7),总览!$K$7,IF(AND(总览!$H$7<>"",B17*100+VALUE(LEFT(C17,LEN(C17)-1))>=总览!$H$7),总览!$I$7,IF(AND(总览!$F$7<>"",B17*100+VALUE(LEFT(C17,LEN(C17)-1))>=总览!$F$7),总览!$G$7,IF(AND(总览!$D$7<>"",B17*100+VALUE(LEFT(C17,LEN(C17)-1))>=总览!$D$7),总览!$E$7,总览!$B$7))))),0) | F17: =ROUND(O16*总览!$B$14/12,0) | G17: =D17+E17+F17 | H17: =IF(OR(B17>2027,AND(B17=2027,VALUE(LEFT(C17,LEN(C17)-1))>=9)),IF(AND(总览!$L$10<>"",B17*100+VALUE(LEFT(C17,LEN(C17)-1))>=总览!$L$10),总览!$M$10,IF(AND(总览!$J$10<>"",B17*100+VALUE(LEFT(C17,LEN(C17)-1))>=总览!$J$10),总览!$K$10,IF(AND(总览!$H$10<>"",B17*100+VALUE(LEFT(C17,LEN(C17)-1))>=总览!$H$10),总览!$I$10,IF(AND(总览!$F$10<>"",B17*100+VALUE(LEFT(C17,LEN(C17)-1))>=总览!$F$10),总览!$G$10,IF(AND(总览!$D$10<>"",B17*100+VALUE(LEFT(C17,LEN(C17)-1))>=总览!$D$10),总览!$E$10,总览!$B$10))))),IF(AND(总览!$L$9<>"",B17*100+VALUE(LEFT(C17,LEN(C17)-1))>=总览!$L$9),总览!$M$9,IF(AND(总览!$J$9<>"",B17*100+VALUE(LEFT(C17,LEN(C17)-1))>=总览!$J$9),总览!$K$9,IF(AND(总览!$H$9<>"",B17*100+VALUE(LEFT(C17,LEN(C17)-1))>=总览!$H$9),总览!$I$9,IF(AND(总览!$F$9<>"",B17*100+VALUE(LEFT(C17,LEN(C17)-1))>=总览!$F$9),总览!$G$9,IF(AND(总览!$D$9<>"",B17*100+VALUE(LEFT(C17,LEN(C17)-1))>=总览!$D$9),总览!$E$9,总览!$B$9)))))) | I17: =IF(AND(总览!$L$11<>"",B17*100+VALUE(LEFT(C17,LEN(C17)-1))>=总览!$L$11),总览!$M$11,IF(AND(总览!$J$11<>"",B17*100+VALUE(LEFT(C17,LEN(C17)-1))>=总览!$J$11),总览!$K$11,IF(AND(总览!$H$11<>"",B17*100+VALUE(LEFT(C17,LEN(C17)-1))>=总览!$H$11),总览!$I$11,IF(AND(总览!$F$11<>"",B17*100+VALUE(LEFT(C17,LEN(C17)-1))>=总览!$F$11),总览!$G$11,IF(AND(总览!$D$11<>"",B17*100+VALUE(LEFT(C17,LEN(C17)-1))>=总览!$D$11),总览!$E$11,总览!$B$11))))) | J17: =IF(OR(B17>2027,AND(B17=2027,VALUE(LEFT(C17,LEN(C17)-1))>=9)),IF(AND(总览!$L$12<>"",B17*100+VALUE(LEFT(C17,LEN(C17)-1))>=总览!$L$12),总览!$M$12,IF(AND(总览!$J$12<>"",B17*100+VALUE(LEFT(C17,LEN(C17)-1))>=总览!$J$12),总览!$K$12,IF(AND(总览!$H$12<>"",B17*100+VALUE(LEFT(C17,LEN(C17)-1))>=总览!$H$12),总览!$I$12,IF(AND(总览!$F$12<>"",B17*100+VALUE(LEFT(C17,LEN(C17)-1))>=总览!$F$12),总览!$G$12,IF(AND(总览!$D$12<>"",B17*100+VALUE(LEFT(C17,LEN(C17)-1))>=总览!$D$12),总览!$E$12,总览!$B$12))))),0) | K17: =IF(AND(B17=2026,C17="5月"),120000,IF(AND(B17=2027,C17="9月"),30000,IF(C17="10月",IF(AND(总览!$L$13<>"",B17*100+VALUE(LEFT(C17,LEN(C17)-1))>=总览!$L$13),总览!$M$13,IF(AND(总览!$J$13<>"",B17*100+VALUE(LEFT(C17,LEN(C17)-1))>=总览!$J$13),总览!$K$13,IF(AND(总览!$H$13<>"",B17*100+VALUE(LEFT(C17,LEN(C17)-1))>=总览!$H$13),总览!$I$13,IF(AND(总览!$F$13<>"",B17*100+VALUE(LEFT(C17,LEN(C17)-1))>=总览!$F$13),总览!$G$13,IF(AND(总览!$D$13<>"",B17*100+VALUE(LEFT(C17,LEN(C17)-1))>=总览!$D$13),总览!$E$13,总览!$B$13))))),0))) | M17: =SUM(H17:K17) | N17: =G17-M17 | O17: =O16+N17
A18: 17 | B18: 2027 | C18: 6月 | D18: =IF(AND(总览!$L$6<>"",B18*100+VALUE(LEFT(C18,LEN(C18)-1))>=总览!$L$6),总览!$M$6,IF(AND(总览!$J$6<>"",B18*100+VALUE(LEFT(C18,LEN(C18)-1))>=总览!$J$6),总览!$K$6,IF(AND(总览!$H$6<>"",B18*100+VALUE(LEFT(C18,LEN(C18)-1))>=总览!$H$6),总览!$I$6,IF(AND(总览!$F$6<>"",B18*100+VALUE(LEFT(C18,LEN(C18)-1))>=总览!$F$6),总览!$G$6,IF(AND(总览!$D$6<>"",B18*100+VALUE(LEFT(C18,LEN(C18)-1))>=总览!$D$6),总览!$E$6,总览!$B$6))))) | E18: =IF(C18="12月",IF(AND(总览!$L$7<>"",B18*100+VALUE(LEFT(C18,LEN(C18)-1))>=总览!$L$7),总览!$M$7,IF(AND(总览!$J$7<>"",B18*100+VALUE(LEFT(C18,LEN(C18)-1))>=总览!$J$7),总览!$K$7,IF(AND(总览!$H$7<>"",B18*100+VALUE(LEFT(C18,LEN(C18)-1))>=总览!$H$7),总览!$I$7,IF(AND(总览!$F$7<>"",B18*100+VALUE(LEFT(C18,LEN(C18)-1))>=总览!$F$7),总览!$G$7,IF(AND(总览!$D$7<>"",B18*100+VALUE(LEFT(C18,LEN(C18)-1))>=总览!$D$7),总览!$E$7,总览!$B$7))))),0) | F18: =ROUND(O17*总览!$B$14/12,0) | G18: =D18+E18+F18 | H18: =IF(OR(B18>2027,AND(B18=2027,VALUE(LEFT(C18,LEN(C18)-1))>=9)),IF(AND(总览!$L$10<>"",B18*100+VALUE(LEFT(C18,LEN(C18)-1))>=总览!$L$10),总览!$M$10,IF(AND(总览!$J$10<>"",B18*100+VALUE(LEFT(C18,LEN(C18)-1))>=总览!$J$10),总览!$K$10,IF(AND(总览!$H$10<>"",B18*100+VALUE(LEFT(C18,LEN(C18)-1))>=总览!$H$10),总览!$I$10,IF(AND(总览!$F$10<>"",B18*100+VALUE(LEFT(C18,LEN(C18)-1))>=总览!$F$10),总览!$G$10,IF(AND(总览!$D$10<>"",B18*100+VALUE(LEFT(C18,LEN(C18)-1))>=总览!$D$10),总览!$E$10,总览!$B$10))))),IF(AND(总览!$L$9<>"",B18*100+VALUE(LEFT(C18,LEN(C18)-1))>=总览!$L$9),总览!$M$9,IF(AND(总览!$J$9<>"",B18*100+VALUE(LEFT(C18,LEN(C18)-1))>=总览!$J$9),总览!$K$9,IF(AND(总览!$H$9<>"",B18*100+VALUE(LEFT(C18,LEN(C18)-1))>=总览!$H$9),总览!$I$9,IF(AND(总览!$F$9<>"",B18*100+VALUE(LEFT(C18,LEN(C18)-1))>=总览!$F$9),总览!$G$9,IF(AND(总览!$D$9<>"",B18*100+VALUE(LEFT(C18,LEN(C18)-1))>=总览!$D$9),总览!$E$9,总览!$B$9)))))) | I18: =IF(AND(总览!$L$11<>"",B18*100+VALUE(LEFT(C18,LEN(C18)-1))>=总览!$L$11),总览!$M$11,IF(AND(总览!$J$11<>"",B18*100+VALUE(LEFT(C18,LEN(C18)-1))>=总览!$J$11),总览!$K$11,IF(AND(总览!$H$11<>"",B18*100+VALUE(LEFT(C18,LEN(C18)-1))>=总览!$H$11),总览!$I$11,IF(AND(总览!$F$11<>"",B18*100+VALUE(LEFT(C18,LEN(C18)-1))>=总览!$F$11),总览!$G$11,IF(AND(总览!$D$11<>"",B18*100+VALUE(LEFT(C18,LEN(C18)-1))>=总览!$D$11),总览!$E$11,总览!$B$11))))) | J18: =IF(OR(B18>2027,AND(B18=2027,VALUE(LEFT(C18,LEN(C18)-1))>=9)),IF(AND(总览!$L$12<>"",B18*100+VALUE(LEFT(C18,LEN(C18)-1))>=总览!$L$12),总览!$M$12,IF(AND(总览!$J$12<>"",B18*100+VALUE(LEFT(C18,LEN(C18)-1))>=总览!$J$12),总览!$K$12,IF(AND(总览!$H$12<>"",B18*100+VALUE(LEFT(C18,LEN(C18)-1))>=总览!$H$12),总览!$I$12,IF(AND(总览!$F$12<>"",B18*100+VALUE(LEFT(C18,LEN(C18)-1))>=总览!$F$12),总览!$G$12,IF(AND(总览!$D$12<>"",B18*100+VALUE(LEFT(C18,LEN(C18)-1))>=总览!$D$12),总览!$E$12,总览!$B$12))))),0) | K18: =IF(AND(B18=2026,C18="5月"),120000,IF(AND(B18=2027,C18="9月"),30000,IF(C18="10月",IF(AND(总览!$L$13<>"",B18*100+VALUE(LEFT(C18,LEN(C18)-1))>=总览!$L$13),总览!$M$13,IF(AND(总览!$J$13<>"",B18*100+VALUE(LEFT(C18,LEN(C18)-1))>=总览!$J$13),总览!$K$13,IF(AND(总览!$H$13<>"",B18*100+VALUE(LEFT(C18,LEN(C18)-1))>=总览!$H$13),总览!$I$13,IF(AND(总览!$F$13<>"",B18*100+VALUE(LEFT(C18,LEN(C18)-1))>=总览!$F$13),总览!$G$13,IF(AND(总览!$D$13<>"",B18*100+VALUE(LEFT(C18,LEN(C18)-1))>=总览!$D$13),总览!$E$13,总览!$B$13))))),0))) | M18: =SUM(H18:K18) | N18: =G18-M18 | O18: =O17+N18
